<?xml version="1.0" ?>
<robot name="3." xmlns:xacro="http://www.ros.org/wiki/xacro">

<xacro:include filename="$(find description)/urdf/materials.xacro" />
<xacro:include filename="$(find description)/urdf/3..trans" />
<xacro:include filename="$(find description)/urdf/3..gazebo" />
<link name="base_link">
  <inertial>
    <origin xyz="-0.36129856307510333 -0.2353371035810301 0.198275205289386" rpy="0 0 0"/>
    <mass value="48.99149294347192"/>
    <inertia ixx="3.968598" iyy="5.247303" izz="3.390587" ixy="-0.022425" iyz="0.250275" ixz="0.602745"/>
  </inertial>
  <visual>
    <origin xyz="0 0 0" rpy="0 0 0"/>
    <geometry>
      <mesh filename="file://$(find description)/meshes/base_link.stl" scale="0.001 0.001 0.001"/>
    </geometry>
    <material name="silver"/>
  </visual>
  <collision>
    <origin xyz="0 0 0" rpy="0 0 0"/>
    <geometry>
      <mesh filename="file://$(find description)/meshes/base_link.stl" scale="0.001 0.001 0.001"/>
    </geometry>
  </collision>
</link>

<link name="1._pivot_steering_v2_1">
  <inertial>
    <origin xyz="0.0013327059020717402 -0.14344220376800837 0.041707356384150046" rpy="0 0 0"/>
    <mass value="9.811514021273375"/>
    <inertia ixx="0.064211" iyy="1.826132" izz="1.795757" ixy="2.9e-05" iyz="0.001127" ixz="0.044969"/>
  </inertial>
  <visual>
    <origin xyz="0.3 0.448 -0.09" rpy="0 0 0"/>
    <geometry>
      <mesh filename="file://$(find description)/meshes/1._pivot_steering_v2_1.stl" scale="0.001 0.001 0.001"/>
    </geometry>
    <material name="silver"/>
  </visual>
  <collision>
    <origin xyz="0.3 0.448 -0.09" rpy="0 0 0"/>
    <geometry>
      <mesh filename="file://$(find description)/meshes/1._pivot_steering_v2_1.stl" scale="0.001 0.001 0.001"/>
    </geometry>
  </collision>
</link>

<link name="1._pivot_steering_v2_2">
  <inertial>
    <origin xyz="0.0023074010701228387 0.14344220376800892 0.04166480027410846" rpy="0 0 0"/>
    <mass value="9.811514021273375"/>
    <inertia ixx="0.069555" iyy="1.826132" izz="1.790413" ixy="-6.9e-05" iyz="-0.001125" ixz="0.106054"/>
  </inertial>
  <visual>
    <origin xyz="0.3 -0.003 -0.091" rpy="0 0 0"/>
    <geometry>
      <mesh filename="file://$(find description)/meshes/1._pivot_steering_v2_2.stl" scale="0.001 0.001 0.001"/>
    </geometry>
    <material name="silver"/>
  </visual>
  <collision>
    <origin xyz="0.3 -0.003 -0.091" rpy="0 0 0"/>
    <geometry>
      <mesh filename="file://$(find description)/meshes/1._pivot_steering_v2_2.stl" scale="0.001 0.001 0.001"/>
    </geometry>
  </collision>
</link>

<link name="1._driving_v2_1">
  <inertial>
    <origin xyz="-0.05336323228963802 -0.001790241868722009 -0.2361120772140211" rpy="0 0 0"/>
    <mass value="2.150656122682915"/>
    <inertia ixx="0.013956" iyy="0.016641" izz="0.003749" ixy="-0.0001" iyz="-6.9e-05" ixz="-0.002335"/>
  </inertial>
  <visual>
    <origin xyz="-0.116011 0.591408 -0.062747" rpy="0 0 0"/>
    <geometry>
      <mesh filename="file://$(find description)/meshes/1._driving_v2_1.stl" scale="0.001 0.001 0.001"/>
    </geometry>
    <material name="silver"/>
  </visual>
  <collision>
    <origin xyz="-0.116011 0.591408 -0.062747" rpy="0 0 0"/>
    <geometry>
      <mesh filename="file://$(find description)/meshes/1._driving_v2_1.stl" scale="0.001 0.001 0.001"/>
    </geometry>
  </collision>
</link>

<link name="1._driving_v2_3">
  <inertial>
    <origin xyz="-0.05336302206809551 -0.001790241868722231 -0.23611208152895444" rpy="0 0 0"/>
    <mass value="2.150656122682915"/>
    <inertia ixx="0.013956" iyy="0.016641" izz="0.003749" ixy="-0.0001" iyz="-6.9e-05" ixz="-0.002335"/>
  </inertial>
  <visual>
    <origin xyz="0.716864 0.591408 -0.084264" rpy="0 0 0"/>
    <geometry>
      <mesh filename="file://$(find description)/meshes/1._driving_v2_3.stl" scale="0.001 0.001 0.001"/>
    </geometry>
    <material name="silver"/>
  </visual>
  <collision>
    <origin xyz="0.716864 0.591408 -0.084264" rpy="0 0 0"/>
    <geometry>
      <mesh filename="file://$(find description)/meshes/1._driving_v2_3.stl" scale="0.001 0.001 0.001"/>
    </geometry>
  </collision>
</link>

<link name="1._driving_v2_2">
  <inertial>
    <origin xyz="-0.06173523819166351 -0.0017906129843300866 -0.23406282227931108" rpy="0 0 0"/>
    <mass value="2.150656122682915"/>
    <inertia ixx="0.013777" iyy="0.016641" izz="0.003928" ixy="-0.000102" iyz="-6.5e-05" ixz="-0.002692"/>
  </inertial>
  <visual>
    <origin xyz="-0.114777 -0.146408 -0.048954" rpy="0 0 0"/>
    <geometry>
      <mesh filename="file://$(find description)/meshes/1._driving_v2_2.stl" scale="0.001 0.001 0.001"/>
    </geometry>
    <material name="silver"/>
  </visual>
  <collision>
    <origin xyz="-0.114777 -0.146408 -0.048954" rpy="0 0 0"/>
    <geometry>
      <mesh filename="file://$(find description)/meshes/1._driving_v2_2.stl" scale="0.001 0.001 0.001"/>
    </geometry>
  </collision>
</link>

<link name="1._driving_v2_4">
  <inertial>
    <origin xyz="-0.061736017683869604 -0.0017906129843306695 -0.234062118380695" rpy="0 0 0"/>
    <mass value="2.150656122682915"/>
    <inertia ixx="0.013777" iyy="0.016641" izz="0.003928" ixy="-0.000102" iyz="-6.5e-05" ixz="-0.002692"/>
  </inertial>
  <visual>
    <origin xyz="0.716803 -0.146408 -0.100108" rpy="0 0 0"/>
    <geometry>
      <mesh filename="file://$(find description)/meshes/1._driving_v2_4.stl" scale="0.001 0.001 0.001"/>
    </geometry>
    <material name="silver"/>
  </visual>
  <collision>
    <origin xyz="0.716803 -0.146408 -0.100108" rpy="0 0 0"/>
    <geometry>
      <mesh filename="file://$(find description)/meshes/1._driving_v2_4.stl" scale="0.001 0.001 0.001"/>
    </geometry>
  </collision>
</link>

<link name="1._wheel_simplified_v2_1">
  <inertial>
    <origin xyz="-0.039472055537907336 -0.0013188678711943402 0.0024275550921873112" rpy="0 0 0"/>
    <mass value="23.722548877018745"/>
    <inertia ixx="0.348962" iyy="0.207419" izz="0.207797" ixy="0.004735" iyz="-0.000291" ixz="-0.008717"/>
  </inertial>
  <visual>
    <origin xyz="-0.139795 -0.147791 0.219889" rpy="0 0 0"/>
    <geometry>
      <mesh filename="file://$(find description)/meshes/1._wheel_simplified_v2_1.stl" scale="0.001 0.001 0.001"/>
    </geometry>
    <material name="silver"/>
  </visual>
  <collision>
    <origin xyz="-0.139795 -0.147791 0.219889" rpy="0 0 0"/>
    <geometry>
      <mesh filename="file://$(find description)/meshes/1._wheel_simplified_v2_1.stl" scale="0.001 0.001 0.001"/>
    </geometry>
  </collision>
</link>

<link name="1._wheel_simplified_v2_3">
  <inertial>
    <origin xyz="-0.03947183503011442 -0.0013188678711952284 0.0024282589908035113" rpy="0 0 0"/>
    <mass value="23.722548877018745"/>
    <inertia ixx="0.348962" iyy="0.207419" izz="0.207797" ixy="0.004735" iyz="-0.000291" ixz="-0.008717"/>
  </inertial>
  <visual>
    <origin xyz="0.691786 -0.147791 0.168735" rpy="0 0 0"/>
    <geometry>
      <mesh filename="file://$(find description)/meshes/1._wheel_simplified_v2_3.stl" scale="0.001 0.001 0.001"/>
    </geometry>
    <material name="silver"/>
  </visual>
  <collision>
    <origin xyz="0.691786 -0.147791 0.168735" rpy="0 0 0"/>
    <geometry>
      <mesh filename="file://$(find description)/meshes/1._wheel_simplified_v2_3.stl" scale="0.001 0.001 0.001"/>
    </geometry>
  </collision>
</link>

<link name="1._wheel_simplified_v2_4">
  <inertial>
    <origin xyz="-0.03953322987191166 -0.0013184967555868177 0.0010210764613669265" rpy="0 0 0"/>
    <mass value="23.722548877018745"/>
    <inertia ixx="0.349404" iyy="0.207419" izz="0.207356" ixy="0.004742" iyz="-0.000122" ixz="-0.003672"/>
  </inertial>
  <visual>
    <origin xyz="-0.150584 0.590025 0.205035" rpy="0 0 0"/>
    <geometry>
      <mesh filename="file://$(find description)/meshes/1._wheel_simplified_v2_4.stl" scale="0.001 0.001 0.001"/>
    </geometry>
    <material name="silver"/>
  </visual>
  <collision>
    <origin xyz="-0.150584 0.590025 0.205035" rpy="0 0 0"/>
    <geometry>
      <mesh filename="file://$(find description)/meshes/1._wheel_simplified_v2_4.stl" scale="0.001 0.001 0.001"/>
    </geometry>
  </collision>
</link>

<link name="1._wheel_simplified_v2_2">
  <inertial>
    <origin xyz="-0.03953301965036915 -0.0013184967555871507 0.0010210721464317118" rpy="0 0 0"/>
    <mass value="23.722548877018745"/>
    <inertia ixx="0.349404" iyy="0.207419" izz="0.207356" ixy="0.004742" iyz="-0.000122" ixz="-0.003672"/>
  </inertial>
  <visual>
    <origin xyz="0.682291 0.590025 0.183518" rpy="0 0 0"/>
    <geometry>
      <mesh filename="file://$(find description)/meshes/1._wheel_simplified_v2_2.stl" scale="0.001 0.001 0.001"/>
    </geometry>
    <material name="silver"/>
  </visual>
  <collision>
    <origin xyz="0.682291 0.590025 0.183518" rpy="0 0 0"/>
    <geometry>
      <mesh filename="file://$(find description)/meshes/1._wheel_simplified_v2_2.stl" scale="0.001 0.001 0.001"/>
    </geometry>
  </collision>
</link>

<link name="1._element_drill_v3_1">
  <inertial>
    <origin xyz="-0.0513141706983431 0.08221396100891368 -0.13869483209325406" rpy="0 0 0"/>
    <mass value="7.507949209271667"/>
    <inertia ixx="0.275242" iyy="0.26604" izz="0.03028" ixy="0.001311" iyz="0.013401" ixz="-0.019318"/>
  </inertial>
  <visual>
    <origin xyz="0.643 0.2975 -0.779165" rpy="0 0 0"/>
    <geometry>
      <mesh filename="file://$(find description)/meshes/1._element_drill_v3_1.stl" scale="0.001 0.001 0.001"/>
    </geometry>
    <material name="silver"/>
  </visual>
  <collision>
    <origin xyz="0.643 0.2975 -0.779165" rpy="0 0 0"/>
    <geometry>
      <mesh filename="file://$(find description)/meshes/1._element_drill_v3_1.stl" scale="0.001 0.001 0.001"/>
    </geometry>
  </collision>
</link>

<link name="1._foret_v2_1">
  <inertial>
    <origin xyz="-9.82439450913919e-06 2.6079352202029726e-05 -0.3388184333033618" rpy="0 0 0"/>
    <mass value="1.9633991132983974"/>
    <inertia ixx="0.069287" iyy="0.069287" izz="0.000163" ixy="0.0" iyz="-2e-06" ixz="-5e-06"/>
  </inertial>
  <visual>
    <origin xyz="0.7185 0.19625 -0.686365" rpy="0 0 0"/>
    <geometry>
      <mesh filename="file://$(find description)/meshes/1._foret_v2_1.stl" scale="0.001 0.001 0.001"/>
    </geometry>
    <material name="silver"/>
  </visual>
  <collision>
    <origin xyz="0.7185 0.19625 -0.686365" rpy="0 0 0"/>
    <geometry>
      <mesh filename="file://$(find description)/meshes/1._foret_v2_1.stl" scale="0.001 0.001 0.001"/>
    </geometry>
  </collision>
</link>

<link name="1.2_J1J2_v2_1">
  <inertial>
    <origin xyz="-0.00019343861423726239 -0.02168276319253387 0.10154404613782636" rpy="0 0 0"/>
    <mass value="4.634126900841572"/>
    <inertia ixx="0.028645" iyy="0.020818" izz="0.018526" ixy="9.3e-05" iyz="0.002659" ixz="-8e-06"/>
  </inertial>
  <visual>
    <origin xyz="0.07 0.2225 -0.195" rpy="0 0 0"/>
    <geometry>
      <mesh filename="file://$(find description)/meshes/1.2_J1J2_v2_1.stl" scale="0.001 0.001 0.001"/>
    </geometry>
    <material name="silver"/>
  </visual>
  <collision>
    <origin xyz="0.07 0.2225 -0.195" rpy="0 0 0"/>
    <geometry>
      <mesh filename="file://$(find description)/meshes/1.2_J1J2_v2_1.stl" scale="0.001 0.001 0.001"/>
    </geometry>
  </collision>
</link>

<link name="1.3_bras_1_v2_1">
  <inertial>
    <origin xyz="4.3021142204224816e-16 0.011067557585022869 0.1859999999999976" rpy="0 0 0"/>
    <mass value="3.1139206406559206"/>
    <inertia ixx="0.067529" iyy="0.069339" izz="0.005977" ixy="0.0" iyz="0.0" ixz="-0.0"/>
  </inertial>
  <visual>
    <origin xyz="0.07 0.341 -0.3135" rpy="0 0 0"/>
    <geometry>
      <mesh filename="file://$(find description)/meshes/1.3_bras_1_v2_1.stl" scale="0.001 0.001 0.001"/>
    </geometry>
    <material name="silver"/>
  </visual>
  <collision>
    <origin xyz="0.07 0.341 -0.3135" rpy="0 0 0"/>
    <geometry>
      <mesh filename="file://$(find description)/meshes/1.3_bras_1_v2_1.stl" scale="0.001 0.001 0.001"/>
    </geometry>
  </collision>
</link>

<link name="1.2_J1J2_v2_3">
  <inertial>
    <origin xyz="0.00019343861423892772 0.0968172368074551 0.016955953862172413" rpy="0 0 0"/>
    <mass value="4.634126900841572"/>
    <inertia ixx="0.028645" iyy="0.020818" izz="0.018526" ixy="-9.3e-05" iyz="-0.002659" ixz="-8e-06"/>
  </inertial>
  <visual>
    <origin xyz="0.07 0.341 -0.6855" rpy="0 0 0"/>
    <geometry>
      <mesh filename="file://$(find description)/meshes/1.2_J1J2_v2_3.stl" scale="0.001 0.001 0.001"/>
    </geometry>
    <material name="silver"/>
  </visual>
  <collision>
    <origin xyz="0.07 0.341 -0.6855" rpy="0 0 0"/>
    <geometry>
      <mesh filename="file://$(find description)/meshes/1.2_J1J2_v2_3.stl" scale="0.001 0.001 0.001"/>
    </geometry>
  </collision>
</link>

<link name="1.4_bras_2_v2_1">
  <inertial>
    <origin xyz="-4.565792188770956e-14 0.003070181009092704 0.18321907839266627" rpy="0 0 0"/>
    <mass value="2.501356467163731"/>
    <inertia ixx="0.0397" iyy="0.040591" izz="0.004603" ixy="0.0" iyz="-0.001154" ixz="0.0"/>
  </inertial>
  <visual>
    <origin xyz="0.07 0.2225 -0.804" rpy="0 0 0"/>
    <geometry>
      <mesh filename="file://$(find description)/meshes/1.4_bras_2_v2_1.stl" scale="0.001 0.001 0.001"/>
    </geometry>
    <material name="silver"/>
  </visual>
  <collision>
    <origin xyz="0.07 0.2225 -0.804" rpy="0 0 0"/>
    <geometry>
      <mesh filename="file://$(find description)/meshes/1.4_bras_2_v2_1.stl" scale="0.001 0.001 0.001"/>
    </geometry>
  </collision>
</link>

<link name="1.2_J1J2_v2_2">
  <inertial>
    <origin xyz="-0.00019343861423705422 -0.09681723680750129 0.01695595386216664" rpy="0 0 0"/>
    <mass value="4.634126900841572"/>
    <inertia ixx="0.028645" iyy="0.020818" izz="0.018526" ixy="-9.3e-05" iyz="0.002659" ixz="8e-06"/>
  </inertial>
  <visual>
    <origin xyz="0.07 0.2065 -1.127" rpy="0 0 0"/>
    <geometry>
      <mesh filename="file://$(find description)/meshes/1.2_J1J2_v2_2.stl" scale="0.001 0.001 0.001"/>
    </geometry>
    <material name="silver"/>
  </visual>
  <collision>
    <origin xyz="0.07 0.2065 -1.127" rpy="0 0 0"/>
    <geometry>
      <mesh filename="file://$(find description)/meshes/1.2_J1J2_v2_2.stl" scale="0.001 0.001 0.001"/>
    </geometry>
  </collision>
</link>

<link name="1_3_gripper_simplifie_single_c_v2_1">
  <inertial>
    <origin xyz="-0.00031786094821995015 -0.0002575140808524501 0.06769985638413667" rpy="0 0 0"/>
    <mass value="0.236737000660016"/>
    <inertia ixx="0.000328" iyy="0.000476" izz="0.00022" ixy="0.0" iyz="1e-06" ixz="-4e-06"/>
  </inertial>
  <visual>
    <origin xyz="0.07 0.325 -1.2455" rpy="0 0 0"/>
    <geometry>
      <mesh filename="file://$(find description)/meshes/1_3_gripper_simplifie_single_c_v2_1.stl" scale="0.001 0.001 0.001"/>
    </geometry>
    <material name="silver"/>
  </visual>
  <collision>
    <origin xyz="0.07 0.325 -1.2455" rpy="0 0 0"/>
    <geometry>
      <mesh filename="file://$(find description)/meshes/1_3_gripper_simplifie_single_c_v2_1.stl" scale="0.001 0.001 0.001"/>
    </geometry>
  </collision>
</link>

<link name="Arm_A_v6_2">
  <inertial>
    <origin xyz="-0.03443129704231715 0.0037499999237549653 -0.01895133656784065" rpy="0 0 0"/>
    <mass value="0.11091056155247334"/>
    <inertia ixx="1.4e-05" iyy="0.000118" izz="0.000106" ixy="-0.0" iyz="-0.0" ixz="1.1e-05"/>
  </inertial>
  <visual>
    <origin xyz="0.085 0.3025 -1.327" rpy="0 0 0"/>
    <geometry>
      <mesh filename="file://$(find description)/meshes/Arm_A_v6_2.stl" scale="0.001 0.001 0.001"/>
    </geometry>
    <material name="silver"/>
  </visual>
  <collision>
    <origin xyz="0.085 0.3025 -1.327" rpy="0 0 0"/>
    <geometry>
      <mesh filename="file://$(find description)/meshes/Arm_A_v6_2.stl" scale="0.001 0.001 0.001"/>
    </geometry>
  </collision>
</link>

<link name="Arm_A_v6_1">
  <inertial>
    <origin xyz="0.03443129704231733 0.0037500000761570007 -0.018951336567840427" rpy="0 0 0"/>
    <mass value="0.11091056155247334"/>
    <inertia ixx="1.4e-05" iyy="0.000118" izz="0.000106" ixy="-0.0" iyz="0.0" ixz="-1.1e-05"/>
  </inertial>
  <visual>
    <origin xyz="0.055 0.3025 -1.327" rpy="0 0 0"/>
    <geometry>
      <mesh filename="file://$(find description)/meshes/Arm_A_v6_1.stl" scale="0.001 0.001 0.001"/>
    </geometry>
    <material name="silver"/>
  </visual>
  <collision>
    <origin xyz="0.055 0.3025 -1.327" rpy="0 0 0"/>
    <geometry>
      <mesh filename="file://$(find description)/meshes/Arm_A_v6_1.stl" scale="0.001 0.001 0.001"/>
    </geometry>
  </collision>
</link>

<link name="Gripper_Finger_v1_1">
  <inertial>
    <origin xyz="7.1709541498155005e-06 -0.022500000000043985 -0.009331481189207125" rpy="0 0 0"/>
    <mass value="0.21136162569656056"/>
    <inertia ixx="5.7e-05" iyy="3.6e-05" izz="3.4e-05" ixy="0.0" iyz="0.0" ixz="-0.0"/>
  </inertial>
  <visual>
    <origin xyz="-0.03158 0.3025 -1.324082" rpy="0 0 0"/>
    <geometry>
      <mesh filename="file://$(find description)/meshes/Gripper_Finger_v1_1.stl" scale="0.001 0.001 0.001"/>
    </geometry>
    <material name="silver"/>
  </visual>
  <collision>
    <origin xyz="-0.03158 0.3025 -1.324082" rpy="0 0 0"/>
    <geometry>
      <mesh filename="file://$(find description)/meshes/Gripper_Finger_v1_1.stl" scale="0.001 0.001 0.001"/>
    </geometry>
  </collision>
</link>

<link name="Gripper_Finger_v1_2">
  <inertial>
    <origin xyz="6.82144932212525e-06 -0.02250000000004415 -0.009331481189207125" rpy="0 0 0"/>
    <mass value="0.21136162569656056"/>
    <inertia ixx="5.7e-05" iyy="3.6e-05" izz="3.4e-05" ixy="0.0" iyz="0.0" ixz="-0.0"/>
  </inertial>
  <visual>
    <origin xyz="0.17158 0.3025 -1.324082" rpy="0 0 0"/>
    <geometry>
      <mesh filename="file://$(find description)/meshes/Gripper_Finger_v1_2.stl" scale="0.001 0.001 0.001"/>
    </geometry>
    <material name="silver"/>
  </visual>
  <collision>
    <origin xyz="0.17158 0.3025 -1.324082" rpy="0 0 0"/>
    <geometry>
      <mesh filename="file://$(find description)/meshes/Gripper_Finger_v1_2.stl" scale="0.001 0.001 0.001"/>
    </geometry>
  </collision>
</link>

<joint name="Revolution 1" type="continuous">
  <origin xyz="-0.3 -0.448 0.09" rpy="0 0 0"/>
  <parent link="base_link"/>
  <child link="1._pivot_steering_v2_1"/>
  <axis xyz="0.0 1.0 -0.0"/>
</joint>

<joint name="Revolution 2" type="continuous">
  <origin xyz="-0.3 0.003 0.091" rpy="0 0 0"/>
  <parent link="base_link"/>
  <child link="1._pivot_steering_v2_2"/>
  <axis xyz="0.0 -1.0 0.0"/>
</joint>

<joint name="Revolution 3" type="continuous">
  <origin xyz="0.416011 -0.143408 -0.027253" rpy="0 0 0"/>
  <parent link="1._pivot_steering_v2_1"/>
  <child link="1._driving_v2_1"/>
  <axis xyz="0.025826 0.0 0.999666"/>
</joint>

<joint name="Revolution 4" type="continuous">
  <origin xyz="-0.416864 -0.143408 -0.005736" rpy="0 0 0"/>
  <parent link="1._pivot_steering_v2_1"/>
  <child link="1._driving_v2_3"/>
  <axis xyz="-0.025826 -0.0 -0.999666"/>
</joint>

<joint name="Revolution 5" type="continuous">
  <origin xyz="0.414777 0.143408 -0.042046" rpy="0 0 0"/>
  <parent link="1._pivot_steering_v2_2"/>
  <child link="1._driving_v2_2"/>
  <axis xyz="-0.061399 0.0 -0.998113"/>
</joint>

<joint name="Revolution 6" type="continuous">
  <origin xyz="-0.416803 0.143408 0.009108" rpy="0 0 0"/>
  <parent link="1._pivot_steering_v2_2"/>
  <child link="1._driving_v2_4"/>
  <axis xyz="0.061399 -0.0 0.998113"/>
</joint>

<joint name="Revolution 7" type="continuous">
  <origin xyz="0.025018 0.001383 -0.268843" rpy="0 0 0"/>
  <parent link="1._driving_v2_2"/>
  <child link="1._wheel_simplified_v2_1"/>
  <axis xyz="0.997559 0.03333 -0.061365"/>
</joint>

<joint name="Revolution 8" type="continuous">
  <origin xyz="0.025017 0.001383 -0.268843" rpy="0 0 0"/>
  <parent link="1._driving_v2_4"/>
  <child link="1._wheel_simplified_v2_3"/>
  <axis xyz="0.997559 0.03333 -0.061365"/>
</joint>

<joint name="Revolution 9" type="continuous">
  <origin xyz="0.034573 0.001383 -0.267782" rpy="0 0 0"/>
  <parent link="1._driving_v2_1"/>
  <child link="1._wheel_simplified_v2_4"/>
  <axis xyz="0.999111 0.03333 -0.025812"/>
</joint>

<joint name="Revolution 10" type="continuous">
  <origin xyz="0.034573 0.001383 -0.267782" rpy="0 0 0"/>
  <parent link="1._driving_v2_3"/>
  <child link="1._wheel_simplified_v2_2"/>
  <axis xyz="0.999111 0.03333 -0.025812"/>
</joint>

<joint name="Glissiere 11" type="prismatic">
  <origin xyz="-0.643 -0.2975 0.779165" rpy="0 0 0"/>
  <parent link="base_link"/>
  <child link="1._element_drill_v3_1"/>
  <axis xyz="0.0 0.0 1.0"/>
  <limit upper="0.0" lower="-0.64" effort="100" velocity="100"/>
</joint>

<joint name="Revolution 12" type="continuous">
  <origin xyz="-0.0755 0.10125 -0.0928" rpy="0 0 0"/>
  <parent link="1._element_drill_v3_1"/>
  <child link="1._foret_v2_1"/>
  <axis xyz="0.0 -0.0 -1.0"/>
</joint>

<joint name="Revolution 13" type="continuous">
  <origin xyz="-0.07 -0.2225 0.195" rpy="0 0 0"/>
  <parent link="base_link"/>
  <child link="1.2_J1J2_v2_1"/>
  <axis xyz="0.0 0.0 -1.0"/>
</joint>

<joint name="Revolution 14" type="continuous">
  <origin xyz="0.0 -0.1185 0.1185" rpy="0 0 0"/>
  <parent link="1.2_J1J2_v2_1"/>
  <child link="1.3_bras_1_v2_1"/>
  <axis xyz="0.0 1.0 0.0"/>
</joint>

<joint name="Revolution 15" type="continuous">
  <origin xyz="0.0 0.0 0.372" rpy="0 0 0"/>
  <parent link="1.3_bras_1_v2_1"/>
  <child link="1.2_J1J2_v2_3"/>
  <axis xyz="-0.0 -1.0 -0.0"/>
</joint>

<joint name="Revolution 16" type="continuous">
  <origin xyz="0.0 0.1185 0.1185" rpy="0 0 0"/>
  <parent link="1.2_J1J2_v2_3"/>
  <child link="1.4_bras_2_v2_1"/>
  <axis xyz="-0.0 0.0 -1.0"/>
</joint>

<joint name="Revolution 17" type="continuous">
  <origin xyz="0.0 0.016 0.323" rpy="0 0 0"/>
  <parent link="1.4_bras_2_v2_1"/>
  <child link="1.2_J1J2_v2_2"/>
  <axis xyz="-0.0 1.0 0.0"/>
</joint>

<joint name="Revolution 18" type="continuous">
  <origin xyz="0.0 -0.1185 0.1185" rpy="0 0 0"/>
  <parent link="1.2_J1J2_v2_2"/>
  <child link="1_3_gripper_simplifie_single_c_v2_1"/>
  <axis xyz="-0.0 0.0 -1.0"/>
</joint>

<joint name="Revolution 19" type="continuous">
  <origin xyz="-0.015 0.0225 0.0815" rpy="0 0 0"/>
  <parent link="1_3_gripper_simplifie_single_c_v2_1"/>
  <child link="Arm_A_v6_2"/>
  <axis xyz="0.0 -1.0 -0.0"/>
</joint>

<joint name="Revolution 20" type="continuous">
  <origin xyz="0.015 0.0225 0.0815" rpy="0 0 0"/>
  <parent link="1_3_gripper_simplifie_single_c_v2_1"/>
  <child link="Arm_A_v6_1"/>
  <axis xyz="0.0 -1.0 -0.0"/>
</joint>

<joint name="Revolution 23" type="continuous">
  <origin xyz="0.08658 0.0 -0.002918" rpy="0 0 0"/>
  <parent link="Arm_A_v6_1"/>
  <child link="Gripper_Finger_v1_1"/>
  <axis xyz="-0.0 1.0 0.0"/>
</joint>

<joint name="Revolution 25" type="continuous">
  <origin xyz="-0.08658 0.0 -0.002918" rpy="0 0 0"/>
  <parent link="Arm_A_v6_2"/>
  <child link="Gripper_Finger_v1_2"/>
  <axis xyz="0.0 -1.0 -0.0"/>
</joint>

</robot>
