<?xml version="1.0" ?>
<robot name="onyx" xmlns:xacro="http://www.ros.org/wiki/xacro">

<xacro:include filename="$(find onyx_description_2)/urdf/materials.xacro" />
<xacro:include filename="$(find onyx_description_2)/urdf/2..trans" />
<xacro:include filename="$(find onyx_description_2)/urdf/2..gazebo" />
<link name="base_link">
  <inertial>
    <origin xyz="-0.3613340319355315 -0.23528546746907128 0.1983872683584351" rpy="0 0 0"/>
    <mass value="48.98789634836586"/>
    <inertia ixx="3.971646" iyy="5.251389" izz="3.390263" ixy="-0.022504" iyz="0.249432" ixz="0.605064"/>
  </inertial>
  <visual>
    <origin xyz="0 0 0" rpy="0 0 0"/>
    <geometry>
      <mesh filename="package://$(find onyx_description_2)/meshes/base_link.stl" scale="0.001 0.001 0.001"/>
    </geometry>
    <material name="silver"/>
  </visual>
  <collision>
    <origin xyz="0 0 0" rpy="0 0 0"/>
    <geometry>
      <mesh filename="package://$(find onyx_description_2)/meshes/base_link.stl" scale="0.001 0.001 0.001"/>
    </geometry>
  </collision>
</link>

<link name="1._pivot_steering_v2_1">
  <inertial>
    <origin xyz="0.0013327059020717402 -0.14344220376800837 0.041707356384150046" rpy="0 0 0"/>
    <mass value="9.811514021273375"/>
    <inertia ixx="0.064211" iyy="1.826132" izz="1.795757" ixy="2.9e-05" iyz="0.001127" ixz="0.044969"/>
  </inertial>
  <visual>
    <origin xyz="0.3 0.448 -0.09" rpy="0 0 0"/>
    <geometry>
      <mesh filename="package://$(find onyx_description_2)/meshes/1._pivot_steering_v2_1.stl" scale="0.001 0.001 0.001"/>
    </geometry>
    <material name="silver"/>
  </visual>
  <collision>
    <origin xyz="0.3 0.448 -0.09" rpy="0 0 0"/>
    <geometry>
      <mesh filename="package://$(find onyx_description_2)/meshes/1._pivot_steering_v2_1.stl" scale="0.001 0.001 0.001"/>
    </geometry>
  </collision>
</link>

<link name="1._pivot_steering_v2_2">
  <inertial>
    <origin xyz="0.0023074010701228387 0.14344220376800892 0.04166480027410846" rpy="0 0 0"/>
    <mass value="9.811514021273375"/>
    <inertia ixx="0.069555" iyy="1.826132" izz="1.790413" ixy="-6.9e-05" iyz="-0.001125" ixz="0.106054"/>
  </inertial>
  <visual>
    <origin xyz="0.3 -0.003 -0.091" rpy="0 0 0"/>
    <geometry>
      <mesh filename="package://$(find onyx_description_2)/meshes/1._pivot_steering_v2_2.stl" scale="0.001 0.001 0.001"/>
    </geometry>
    <material name="silver"/>
  </visual>
  <collision>
    <origin xyz="0.3 -0.003 -0.091" rpy="0 0 0"/>
    <geometry>
      <mesh filename="package://$(find onyx_description_2)/meshes/1._pivot_steering_v2_2.stl" scale="0.001 0.001 0.001"/>
    </geometry>
  </collision>
</link>

<link name="1._driving_v2_1">
  <inertial>
    <origin xyz="-0.05336323228963802 -0.001790241868722009 -0.2361120772140211" rpy="0 0 0"/>
    <mass value="2.150656122682915"/>
    <inertia ixx="0.013956" iyy="0.016641" izz="0.003749" ixy="-0.0001" iyz="-6.9e-05" ixz="-0.002335"/>
  </inertial>
  <visual>
    <origin xyz="-0.116011 0.591408 -0.062747" rpy="0 0 0"/>
    <geometry>
      <mesh filename="package://$(find onyx_description_2)/meshes/1._driving_v2_1.stl" scale="0.001 0.001 0.001"/>
    </geometry>
    <material name="silver"/>
  </visual>
  <collision>
    <origin xyz="-0.116011 0.591408 -0.062747" rpy="0 0 0"/>
    <geometry>
      <mesh filename="package://$(find onyx_description_2)/meshes/1._driving_v2_1.stl" scale="0.001 0.001 0.001"/>
    </geometry>
  </collision>
</link>

<link name="1._driving_v2_3">
  <inertial>
    <origin xyz="-0.05336302206809551 -0.001790241868722231 -0.23611208152895444" rpy="0 0 0"/>
    <mass value="2.150656122682915"/>
    <inertia ixx="0.013956" iyy="0.016641" izz="0.003749" ixy="-0.0001" iyz="-6.9e-05" ixz="-0.002335"/>
  </inertial>
  <visual>
    <origin xyz="0.716864 0.591408 -0.084264" rpy="0 0 0"/>
    <geometry>
      <mesh filename="package://$(find onyx_description_2)/meshes/1._driving_v2_3.stl" scale="0.001 0.001 0.001"/>
    </geometry>
    <material name="silver"/>
  </visual>
  <collision>
    <origin xyz="0.716864 0.591408 -0.084264" rpy="0 0 0"/>
    <geometry>
      <mesh filename="package://$(find onyx_description_2)/meshes/1._driving_v2_3.stl" scale="0.001 0.001 0.001"/>
    </geometry>
  </collision>
</link>

<link name="1._driving_v2_2">
  <inertial>
    <origin xyz="-0.06173523819166351 -0.0017906129843300866 -0.23406282227931108" rpy="0 0 0"/>
    <mass value="2.150656122682915"/>
    <inertia ixx="0.013777" iyy="0.016641" izz="0.003928" ixy="-0.000102" iyz="-6.5e-05" ixz="-0.002692"/>
  </inertial>
  <visual>
    <origin xyz="-0.114777 -0.146408 -0.048954" rpy="0 0 0"/>
    <geometry>
      <mesh filename="package://$(find onyx_description_2)/meshes/1._driving_v2_2.stl" scale="0.001 0.001 0.001"/>
    </geometry>
    <material name="silver"/>
  </visual>
  <collision>
    <origin xyz="-0.114777 -0.146408 -0.048954" rpy="0 0 0"/>
    <geometry>
      <mesh filename="package://$(find onyx_description_2)/meshes/1._driving_v2_2.stl" scale="0.001 0.001 0.001"/>
    </geometry>
  </collision>
</link>

<link name="1._driving_v2_4">
  <inertial>
    <origin xyz="-0.061736017683869604 -0.0017906129843306695 -0.234062118380695" rpy="0 0 0"/>
    <mass value="2.150656122682915"/>
    <inertia ixx="0.013777" iyy="0.016641" izz="0.003928" ixy="-0.000102" iyz="-6.5e-05" ixz="-0.002692"/>
  </inertial>
  <visual>
    <origin xyz="0.716803 -0.146408 -0.100108" rpy="0 0 0"/>
    <geometry>
      <mesh filename="package://$(find onyx_description_2)/meshes/1._driving_v2_4.stl" scale="0.001 0.001 0.001"/>
    </geometry>
    <material name="silver"/>
  </visual>
  <collision>
    <origin xyz="0.716803 -0.146408 -0.100108" rpy="0 0 0"/>
    <geometry>
      <mesh filename="package://$(find onyx_description_2)/meshes/1._driving_v2_4.stl" scale="0.001 0.001 0.001"/>
    </geometry>
  </collision>
</link>

<link name="1._wheel_simplified_v2_1">
  <inertial>
    <origin xyz="-0.039472055537907336 -0.0013188678711943402 0.0024275550921873112" rpy="0 0 0"/>
    <mass value="23.722548877018745"/>
    <inertia ixx="0.348962" iyy="0.207419" izz="0.207797" ixy="0.004735" iyz="-0.000291" ixz="-0.008717"/>
  </inertial>
  <visual>
    <origin xyz="-0.139795 -0.147791 0.219889" rpy="0 0 0"/>
    <geometry>
      <mesh filename="package://$(find onyx_description_2)/meshes/1._wheel_simplified_v2_1.stl" scale="0.001 0.001 0.001"/>
    </geometry>
    <material name="silver"/>
  </visual>
  <collision>
    <origin xyz="-0.139795 -0.147791 0.219889" rpy="0 0 0"/>
    <geometry>
      <mesh filename="package://$(find onyx_description_2)/meshes/1._wheel_simplified_v2_1.stl" scale="0.001 0.001 0.001"/>
    </geometry>
  </collision>
</link>

<link name="1._wheel_simplified_v2_3">
  <inertial>
    <origin xyz="-0.03947183503011442 -0.0013188678711952284 0.0024282589908035113" rpy="0 0 0"/>
    <mass value="23.722548877018745"/>
    <inertia ixx="0.348962" iyy="0.207419" izz="0.207797" ixy="0.004735" iyz="-0.000291" ixz="-0.008717"/>
  </inertial>
  <visual>
    <origin xyz="0.691786 -0.147791 0.168735" rpy="0 0 0"/>
    <geometry>
      <mesh filename="package://$(find onyx_description_2)/meshes/1._wheel_simplified_v2_3.stl" scale="0.001 0.001 0.001"/>
    </geometry>
    <material name="silver"/>
  </visual>
  <collision>
    <origin xyz="0.691786 -0.147791 0.168735" rpy="0 0 0"/>
    <geometry>
      <mesh filename="package://$(find onyx_description_2)/meshes/1._wheel_simplified_v2_3.stl" scale="0.001 0.001 0.001"/>
    </geometry>
  </collision>
</link>

<link name="1._wheel_simplified_v2_4">
  <inertial>
    <origin xyz="-0.03953322987191166 -0.0013184967555868177 0.0010210764613669265" rpy="0 0 0"/>
    <mass value="23.722548877018745"/>
    <inertia ixx="0.349404" iyy="0.207419" izz="0.207356" ixy="0.004742" iyz="-0.000122" ixz="-0.003672"/>
  </inertial>
  <visual>
    <origin xyz="-0.150584 0.590025 0.205035" rpy="0 0 0"/>
    <geometry>
      <mesh filename="package://$(find onyx_description_2)/meshes/1._wheel_simplified_v2_4.stl" scale="0.001 0.001 0.001"/>
    </geometry>
    <material name="silver"/>
  </visual>
  <collision>
    <origin xyz="-0.150584 0.590025 0.205035" rpy="0 0 0"/>
    <geometry>
      <mesh filename="package://$(find onyx_description_2)/meshes/1._wheel_simplified_v2_4.stl" scale="0.001 0.001 0.001"/>
    </geometry>
  </collision>
</link>

<link name="1._wheel_simplified_v2_2">
  <inertial>
    <origin xyz="-0.03953301965036915 -0.0013184967555871507 0.0010210721464317118" rpy="0 0 0"/>
    <mass value="23.722548877018745"/>
    <inertia ixx="0.349404" iyy="0.207419" izz="0.207356" ixy="0.004742" iyz="-0.000122" ixz="-0.003672"/>
  </inertial>
  <visual>
    <origin xyz="0.682291 0.590025 0.183518" rpy="0 0 0"/>
    <geometry>
      <mesh filename="package://$(find onyx_description_2)/meshes/1._wheel_simplified_v2_2.stl" scale="0.001 0.001 0.001"/>
    </geometry>
    <material name="silver"/>
  </visual>
  <collision>
    <origin xyz="0.682291 0.590025 0.183518" rpy="0 0 0"/>
    <geometry>
      <mesh filename="package://$(find onyx_description_2)/meshes/1._wheel_simplified_v2_2.stl" scale="0.001 0.001 0.001"/>
    </geometry>
  </collision>
</link>

<link name="1._element_drill_v3_1">
  <inertial>
    <origin xyz="-0.0513141706983431 0.08221396100891368 -0.13869483209325395" rpy="0 0 0"/>
    <mass value="7.507949209271667"/>
    <inertia ixx="0.275242" iyy="0.26604" izz="0.03028" ixy="0.001311" iyz="0.013401" ixz="-0.019318"/>
  </inertial>
  <visual>
    <origin xyz="0.643 0.2975 -0.779165" rpy="0 0 0"/>
    <geometry>
      <mesh filename="package://$(find onyx_description_2)/meshes/1._element_drill_v3_1.stl" scale="0.001 0.001 0.001"/>
    </geometry>
    <material name="silver"/>
  </visual>
  <collision>
    <origin xyz="0.643 0.2975 -0.779165" rpy="0 0 0"/>
    <geometry>
      <mesh filename="package://$(find onyx_description_2)/meshes/1._element_drill_v3_1.stl" scale="0.001 0.001 0.001"/>
    </geometry>
  </collision>
</link>

<link name="1._foret_v2_1">
  <inertial>
    <origin xyz="-9.824394509250212e-06 2.6079352202057482e-05 -0.3388184333033617" rpy="0 0 0"/>
    <mass value="1.9633991132983974"/>
    <inertia ixx="0.069287" iyy="0.069287" izz="0.000163" ixy="0.0" iyz="-2e-06" ixz="-5e-06"/>
  </inertial>
  <visual>
    <origin xyz="0.7185 0.19625 -0.686365" rpy="0 0 0"/>
    <geometry>
      <mesh filename="package://$(find onyx_description_2)/meshes/1._foret_v2_1.stl" scale="0.001 0.001 0.001"/>
    </geometry>
    <material name="silver"/>
  </visual>
  <collision>
    <origin xyz="0.7185 0.19625 -0.686365" rpy="0 0 0"/>
    <geometry>
      <mesh filename="package://$(find onyx_description_2)/meshes/1._foret_v2_1.stl" scale="0.001 0.001 0.001"/>
    </geometry>
  </collision>
</link>

<link name="1.1_j1j2_v3_1">
  <inertial>
    <origin xyz="-0.00027217681434484053 -0.01874965815887239 0.10480043065496542" rpy="0 0 0"/>
    <mass value="4.344736178343352"/>
    <inertia ixx="0.027954" iyy="0.020469" izz="0.018137" ixy="0.000104" iyz="0.001795" ixz="8e-06"/>
  </inertial>
  <visual>
    <origin xyz="0.07 0.2225 -0.195" rpy="0 0 0"/>
    <geometry>
      <mesh filename="package://$(find onyx_description_2)/meshes/1.1_j1j2_v3_1.stl" scale="0.001 0.001 0.001"/>
    </geometry>
    <material name="silver"/>
  </visual>
  <collision>
    <origin xyz="0.07 0.2225 -0.195" rpy="0 0 0"/>
    <geometry>
      <mesh filename="package://$(find onyx_description_2)/meshes/1.1_j1j2_v3_1.stl" scale="0.001 0.001 0.001"/>
    </geometry>
  </collision>
</link>

<link name="1.1_bras_1_single_c_v2_1">
  <inertial>
    <origin xyz="0.18599999999999656 0.011067557585022869 -1.27675647831893e-15" rpy="0 0 0"/>
    <mass value="3.1139206406559206"/>
    <inertia ixx="0.005977" iyy="0.069339" izz="0.067529" ixy="0.0" iyz="0.0" ixz="0.0"/>
  </inertial>
  <visual>
    <origin xyz="0.07 0.341 -0.3135" rpy="0 0 0"/>
    <geometry>
      <mesh filename="package://$(find onyx_description_2)/meshes/1.1_bras_1_single_c_v2_1.stl" scale="0.001 0.001 0.001"/>
    </geometry>
    <material name="silver"/>
  </visual>
  <collision>
    <origin xyz="0.07 0.341 -0.3135" rpy="0 0 0"/>
    <geometry>
      <mesh filename="package://$(find onyx_description_2)/meshes/1.1_bras_1_single_c_v2_1.stl" scale="0.001 0.001 0.001"/>
    </geometry>
  </collision>
</link>

<link name="1.1_j1j2_v3_3">
  <inertial>
    <origin xyz="-0.0002721768143455483 0.10480043065495545 0.018749658158870752" rpy="0 0 0"/>
    <mass value="4.344736178343352"/>
    <inertia ixx="0.027954" iyy="0.018137" izz="0.020469" ixy="8e-06" iyz="-0.001795" ixz="-0.000104"/>
  </inertial>
  <visual>
    <origin xyz="-0.302 0.341 -0.3135" rpy="0 0 0"/>
    <geometry>
      <mesh filename="package://$(find onyx_description_2)/meshes/1.1_j1j2_v3_3.stl" scale="0.001 0.001 0.001"/>
    </geometry>
    <material name="silver"/>
  </visual>
  <collision>
    <origin xyz="-0.302 0.341 -0.3135" rpy="0 0 0"/>
    <geometry>
      <mesh filename="package://$(find onyx_description_2)/meshes/1.1_j1j2_v3_3.stl" scale="0.001 0.001 0.001"/>
    </geometry>
  </collision>
</link>

<link name="1.1_bras_2_single_c_v2_1">
  <inertial>
    <origin xyz="-5.090372567906343e-14 0.0033315049373294214 0.15487679697152218" rpy="0 0 0"/>
    <mass value="2.3051495546208427"/>
    <inertia ixx="0.026991" iyy="0.027883" izz="0.004302" ixy="0.0" iyz="-0.00098" ixz="0.0"/>
  </inertial>
  <visual>
    <origin xyz="-0.302 0.2225 -0.432" rpy="0 0 0"/>
    <geometry>
      <mesh filename="package://$(find onyx_description_2)/meshes/1.1_bras_2_single_c_v2_1.stl" scale="0.001 0.001 0.001"/>
    </geometry>
    <material name="silver"/>
  </visual>
  <collision>
    <origin xyz="-0.302 0.2225 -0.432" rpy="0 0 0"/>
    <geometry>
      <mesh filename="package://$(find onyx_description_2)/meshes/1.1_bras_2_single_c_v2_1.stl" scale="0.001 0.001 0.001"/>
    </geometry>
  </collision>
</link>

<link name="1.1_j1j2_v3_2">
  <inertial>
    <origin xyz="0.00027217681433833185 -0.10480043065497505 0.018749658158869087" rpy="0 0 0"/>
    <mass value="4.344736178343352"/>
    <inertia ixx="0.027954" iyy="0.018137" izz="0.020469" ixy="8e-06" iyz="0.001795" ixz="0.000104"/>
  </inertial>
  <visual>
    <origin xyz="-0.302 0.2065 -0.704" rpy="0 0 0"/>
    <geometry>
      <mesh filename="package://$(find onyx_description_2)/meshes/1.1_j1j2_v3_2.stl" scale="0.001 0.001 0.001"/>
    </geometry>
    <material name="silver"/>
  </visual>
  <collision>
    <origin xyz="-0.302 0.2065 -0.704" rpy="0 0 0"/>
    <geometry>
      <mesh filename="package://$(find onyx_description_2)/meshes/1.1_j1j2_v3_2.stl" scale="0.001 0.001 0.001"/>
    </geometry>
  </collision>
</link>

<link name="1.1_gripper_single_c_v2_1">
  <inertial>
    <origin xyz="-0.00012272189334172623 -0.00013910374700421002 0.049867298136252125" rpy="0 0 0"/>
    <mass value="0.4705692004888986"/>
    <inertia ixx="0.001186" iyy="0.001335" izz="0.000306" ixy="0.0" iyz="4e-06" ixz="0.0"/>
  </inertial>
  <visual>
    <origin xyz="-0.302 0.325 -0.8225" rpy="0 0 0"/>
    <geometry>
      <mesh filename="package://$(find onyx_description_2)/meshes/1.1_gripper_single_c_v2_1.stl" scale="0.001 0.001 0.001"/>
    </geometry>
    <material name="silver"/>
  </visual>
  <collision>
    <origin xyz="-0.302 0.325 -0.8225" rpy="0 0 0"/>
    <geometry>
      <mesh filename="package://$(find onyx_description_2)/meshes/1.1_gripper_single_c_v2_1.stl" scale="0.001 0.001 0.001"/>
    </geometry>
  </collision>
</link>

<link name="Arm_A_v6_2">
  <inertial>
    <origin xyz="0.018951414122021337 -0.003749922369615577 0.03443129704231307" rpy="0 0 0"/>
    <mass value="0.11091056155247334"/>
    <inertia ixx="0.000106" iyy="0.000118" izz="1.4e-05" ixy="-0.0" iyz="-0.0" ixz="1.1e-05"/>
  </inertial>
  <visual>
    <origin xyz="-0.31698 0.34752 -0.9272" rpy="0 0 0"/>
    <geometry>
      <mesh filename="package://$(find onyx_description_2)/meshes/Arm_A_v6_2.stl" scale="0.001 0.001 0.001"/>
    </geometry>
    <material name="silver"/>
  </visual>
  <collision>
    <origin xyz="-0.31698 0.34752 -0.9272" rpy="0 0 0"/>
    <geometry>
      <mesh filename="package://$(find onyx_description_2)/meshes/Arm_A_v6_2.stl" scale="0.001 0.001 0.001"/>
    </geometry>
  </collision>
</link>

<link name="Finger_v1_1">
  <inertial>
    <origin xyz="0.009336809759994846 0.022500081170689412 8.540730690231868e-06" rpy="0 0 0"/>
    <mass value="0.21086382762249625"/>
    <inertia ixx="3.4e-05" iyy="3.6e-05" izz="5.6e-05" ixy="0.0" iyz="0.0" ixz="0.0"/>
  </inertial>
  <visual>
    <origin xyz="-0.319898 0.34752 -1.01378" rpy="0 0 0"/>
    <geometry>
      <mesh filename="package://$(find onyx_description_2)/meshes/Finger_v1_1.stl" scale="0.001 0.001 0.001"/>
    </geometry>
    <material name="silver"/>
  </visual>
  <collision>
    <origin xyz="-0.319898 0.34752 -1.01378" rpy="0 0 0"/>
    <geometry>
      <mesh filename="package://$(find onyx_description_2)/meshes/Finger_v1_1.stl" scale="0.001 0.001 0.001"/>
    </geometry>
  </collision>
</link>

<link name="Arm_A_v6_1">
  <inertial>
    <origin xyz="-0.018951259013647637 -0.0037499225220117838 0.034431297042313624" rpy="0 0 0"/>
    <mass value="0.11091056155247334"/>
    <inertia ixx="0.000106" iyy="0.000118" izz="1.4e-05" ixy="-0.0" iyz="0.0" ixz="-1.1e-05"/>
  </inertial>
  <visual>
    <origin xyz="-0.28698 0.34752 -0.9272" rpy="0 0 0"/>
    <geometry>
      <mesh filename="package://$(find onyx_description_2)/meshes/Arm_A_v6_1.stl" scale="0.001 0.001 0.001"/>
    </geometry>
    <material name="silver"/>
  </visual>
  <collision>
    <origin xyz="-0.28698 0.34752 -0.9272" rpy="0 0 0"/>
    <geometry>
      <mesh filename="package://$(find onyx_description_2)/meshes/Arm_A_v6_1.stl" scale="0.001 0.001 0.001"/>
    </geometry>
  </collision>
</link>

<link name="Finger_v1_2">
  <inertial>
    <origin xyz="-0.00933665465162059 0.022500073937683163 8.540730690898002e-06" rpy="0 0 0"/>
    <mass value="0.21086382762249625"/>
    <inertia ixx="3.4e-05" iyy="3.6e-05" izz="5.6e-05" ixy="0.0" iyz="-0.0" ixz="-0.0"/>
  </inertial>
  <visual>
    <origin xyz="-0.284062 0.34752 -1.01378" rpy="0 0 0"/>
    <geometry>
      <mesh filename="package://$(find onyx_description_2)/meshes/Finger_v1_2.stl" scale="0.001 0.001 0.001"/>
    </geometry>
    <material name="silver"/>
  </visual>
  <collision>
    <origin xyz="-0.284062 0.34752 -1.01378" rpy="0 0 0"/>
    <geometry>
      <mesh filename="package://$(find onyx_description_2)/meshes/Finger_v1_2.stl" scale="0.001 0.001 0.001"/>
    </geometry>
  </collision>
</link>

<joint name="Revolution 1" type="continuous">
  <origin xyz="-0.3 -0.448 0.09" rpy="0 0 0"/>
  <parent link="base_link"/>
  <child link="1._pivot_steering_v2_1"/>
  <axis xyz="0.0 1.0 -0.0"/>
</joint>

<joint name="Revolution 2" type="continuous">
  <origin xyz="-0.3 0.003 0.091" rpy="0 0 0"/>
  <parent link="base_link"/>
  <child link="1._pivot_steering_v2_2"/>
  <axis xyz="0.0 -1.0 0.0"/>
</joint>

<joint name="Revolution 3" type="continuous">
  <origin xyz="0.416011 -0.143408 -0.027253" rpy="0 0 0"/>
  <parent link="1._pivot_steering_v2_1"/>
  <child link="1._driving_v2_1"/>
  <axis xyz="0.025826 0.0 0.999666"/>
</joint>

<joint name="Revolution 4" type="continuous">
  <origin xyz="-0.416864 -0.143408 -0.005736" rpy="0 0 0"/>
  <parent link="1._pivot_steering_v2_1"/>
  <child link="1._driving_v2_3"/>
  <axis xyz="-0.025826 -0.0 -0.999666"/>
</joint>

<joint name="Revolution 5" type="continuous">
  <origin xyz="0.414777 0.143408 -0.042046" rpy="0 0 0"/>
  <parent link="1._pivot_steering_v2_2"/>
  <child link="1._driving_v2_2"/>
  <axis xyz="-0.061399 0.0 -0.998113"/>
</joint>

<joint name="Revolution 6" type="continuous">
  <origin xyz="-0.416803 0.143408 0.009108" rpy="0 0 0"/>
  <parent link="1._pivot_steering_v2_2"/>
  <child link="1._driving_v2_4"/>
  <axis xyz="0.061399 -0.0 0.998113"/>
</joint>

<joint name="Revolution 7" type="continuous">
  <origin xyz="0.025018 0.001383 -0.268843" rpy="0 0 0"/>
  <parent link="1._driving_v2_2"/>
  <child link="1._wheel_simplified_v2_1"/>
  <axis xyz="0.997559 0.03333 -0.061365"/>
</joint>

<joint name="Revolution 8" type="continuous">
  <origin xyz="0.025017 0.001383 -0.268843" rpy="0 0 0"/>
  <parent link="1._driving_v2_4"/>
  <child link="1._wheel_simplified_v2_3"/>
  <axis xyz="0.997559 0.03333 -0.061365"/>
</joint>

<joint name="Revolution 9" type="continuous">
  <origin xyz="0.034573 0.001383 -0.267782" rpy="0 0 0"/>
  <parent link="1._driving_v2_1"/>
  <child link="1._wheel_simplified_v2_4"/>
  <axis xyz="0.999111 0.03333 -0.025812"/>
</joint>

<joint name="Revolution 10" type="continuous">
  <origin xyz="0.034573 0.001383 -0.267782" rpy="0 0 0"/>
  <parent link="1._driving_v2_3"/>
  <child link="1._wheel_simplified_v2_2"/>
  <axis xyz="0.999111 0.03333 -0.025812"/>
</joint>

<joint name="Glissiere 11" type="prismatic">
  <origin xyz="-0.643 -0.2975 0.779165" rpy="0 0 0"/>
  <parent link="base_link"/>
  <child link="1._element_drill_v3_1"/>
  <axis xyz="0.0 0.0 1.0"/>
  <limit upper="0.0" lower="-0.64" effort="100" velocity="100"/>
</joint>

<joint name="Revolution 12" type="continuous">
  <origin xyz="-0.0755 0.10125 -0.0928" rpy="0 0 0"/>
  <parent link="1._element_drill_v3_1"/>
  <child link="1._foret_v2_1"/>
  <axis xyz="0.0 -0.0 -1.0"/>
</joint>

<joint name="Revolution 13" type="continuous">
  <origin xyz="-0.07 -0.2225 0.195" rpy="0 0 0"/>
  <parent link="base_link"/>
  <child link="1.1_j1j2_v3_1"/>
  <axis xyz="0.0 0.0 -1.0"/>
</joint>

<joint name="Revolution 14" type="continuous">
  <origin xyz="0.0 -0.1185 0.1185" rpy="0 0 0"/>
  <parent link="1.1_j1j2_v3_1"/>
  <child link="1.1_bras_1_single_c_v2_1"/>
  <axis xyz="0.0 1.0 0.0"/>
</joint>

<joint name="Revolution 15" type="continuous">
  <origin xyz="0.372 0.0 0.0" rpy="0 0 0"/>
  <parent link="1.1_bras_1_single_c_v2_1"/>
  <child link="1.1_j1j2_v3_3"/>
  <axis xyz="-0.0 -1.0 0.0"/>
</joint>

<joint name="Revolution 16" type="continuous">
  <origin xyz="0.0 0.1185 0.1185" rpy="0 0 0"/>
  <parent link="1.1_j1j2_v3_3"/>
  <child link="1.1_bras_2_single_c_v2_1"/>
  <axis xyz="0.0 -0.0 -1.0"/>
</joint>

<joint name="Revolution 17" type="continuous">
  <origin xyz="0.0 0.016 0.272" rpy="0 0 0"/>
  <parent link="1.1_bras_2_single_c_v2_1"/>
  <child link="1.1_j1j2_v3_2"/>
  <axis xyz="0.0 1.0 -0.0"/>
</joint>

<joint name="Revolution 18" type="continuous">
  <origin xyz="0.0 -0.1185 0.1185" rpy="0 0 0"/>
  <parent link="1.1_j1j2_v3_2"/>
  <child link="1.1_gripper_single_c_v2_1"/>
  <axis xyz="0.0 -0.0 -1.0"/>
</joint>

<joint name="Revolution 19" type="continuous">
  <origin xyz="0.01498 -0.02252 0.1047" rpy="0 0 0"/>
  <parent link="1.1_gripper_single_c_v2_1"/>
  <child link="Arm_A_v6_2"/>
  <axis xyz="0.0 1.0 -0.0"/>
</joint>

<joint name="Revolution 20" type="continuous">
  <origin xyz="0.002918 0.0 0.08658" rpy="0 0 0"/>
  <parent link="Arm_A_v6_2"/>
  <child link="Finger_v1_1"/>
  <axis xyz="-0.0 -1.0 0.0"/>
</joint>

<joint name="Revolution 21" type="continuous">
  <origin xyz="-0.01502 -0.02252 0.1047" rpy="0 0 0"/>
  <parent link="1.1_gripper_single_c_v2_1"/>
  <child link="Arm_A_v6_1"/>
  <axis xyz="0.0 1.0 -0.0"/>
</joint>

<joint name="Revolution 22" type="continuous">
  <origin xyz="-0.002918 0.0 0.08658" rpy="0 0 0"/>
  <parent link="Arm_A_v6_1"/>
  <child link="Finger_v1_2"/>
  <axis xyz="-0.0 -1.0 0.0"/>
</joint>

</robot>
