<?xml version="1.0" ?>
<!-- =================================================================================== -->
<!-- |    This document was autogenerated by xacro from 2..xacro                       | -->
<!-- |    EDITING THIS FILE BY HAND IS NOT RECOMMENDED                                 | -->
<!-- =================================================================================== -->
<robot name="onyx">
  <material name="silver">
  <color rgba="0.700 0.700 0.700 1.000"/>
</material>

<material name="black">
    <color rgba="0.0 0.0 0.0 1.0"/>
  </material>

  <material name="grey_transparent">
    <color rgba="0.2 0.2 0.2 0.5"/>
  </material>

  <material name="grey">
    <color rgba="0.2 0.2 0.2 1.0"/>
  </material>

  <material name="red">
    <color rgba="0.3686 0.0863 0.0863 1.0"/>
  </material>

  <material name="white">
    <color rgba="1.0 1.0 1.0 1.0"/>
  </material>
  <transmission name="pivot_right_tran">
    <type>transmission_interface/SimpleTransmission</type>
    <joint name="pivot_right">
      <hardwareInterface>hardware_interface/EffortJointInterface</hardwareInterface>
    </joint>
    <actuator name="pivot_right_actr">
      <hardwareInterface>hardware_interface/EffortJointInterface</hardwareInterface>
      <mechanicalReduction>1</mechanicalReduction>
    </actuator>
  </transmission>
  <transmission name="pivot_left_tran">
    <type>transmission_interface/SimpleTransmission</type>
    <joint name="pivot_left">
      <hardwareInterface>hardware_interface/EffortJointInterface</hardwareInterface>
    </joint>
    <actuator name="pivot_left_actr">
      <hardwareInterface>hardware_interface/EffortJointInterface</hardwareInterface>
      <mechanicalReduction>1</mechanicalReduction>
    </actuator>
  </transmission>
  <transmission name="wheel_steering_2_tran">
    <type>transmission_interface/SimpleTransmission</type>
    <joint name="wheel_steering_2">
      <hardwareInterface>hardware_interface/EffortJointInterface</hardwareInterface>
    </joint>
    <actuator name="wheel_steering_2_actr">
      <hardwareInterface>hardware_interface/EffortJointInterface</hardwareInterface>
      <mechanicalReduction>1</mechanicalReduction>
    </actuator>
  </transmission>
  <transmission name="wheel_steering_4_tran">
    <type>transmission_interface/SimpleTransmission</type>
    <joint name="wheel_steering_4">
      <hardwareInterface>hardware_interface/EffortJointInterface</hardwareInterface>
    </joint>
    <actuator name="wheel_steering_4_actr">
      <hardwareInterface>hardware_interface/EffortJointInterface</hardwareInterface>
      <mechanicalReduction>1</mechanicalReduction>
    </actuator>
  </transmission>
  <transmission name="wheel_steering_1_tran">
    <type>transmission_interface/SimpleTransmission</type>
    <joint name="wheel_steering_1">
      <hardwareInterface>hardware_interface/EffortJointInterface</hardwareInterface>
    </joint>
    <actuator name="wheel_steering_1_actr">
      <hardwareInterface>hardware_interface/EffortJointInterface</hardwareInterface>
      <mechanicalReduction>1</mechanicalReduction>
    </actuator>
  </transmission>
  <transmission name="wheel_steering_3_tran">
    <type>transmission_interface/SimpleTransmission</type>
    <joint name="wheel_steering_3">
      <hardwareInterface>hardware_interface/EffortJointInterface</hardwareInterface>
    </joint>
    <actuator name="wheel_steering_3_actr">
      <hardwareInterface>hardware_interface/EffortJointInterface</hardwareInterface>
      <mechanicalReduction>1</mechanicalReduction>
    </actuator>
  </transmission>
  <transmission name="wheel_driving_1_tran">
    <type>transmission_interface/SimpleTransmission</type>
    <joint name="wheel_driving_1">
      <hardwareInterface>hardware_interface/EffortJointInterface</hardwareInterface>
    </joint>
    <actuator name="wheel_driving_1_actr">
      <hardwareInterface>hardware_interface/EffortJointInterface</hardwareInterface>
      <mechanicalReduction>1</mechanicalReduction>
    </actuator>
  </transmission>
  <transmission name="wheel_driving_3_tran">
    <type>transmission_interface/SimpleTransmission</type>
    <joint name="wheel_driving_3">
      <hardwareInterface>hardware_interface/EffortJointInterface</hardwareInterface>
    </joint>
    <actuator name="wheel_driving_3_actr">
      <hardwareInterface>hardware_interface/EffortJointInterface</hardwareInterface>
      <mechanicalReduction>1</mechanicalReduction>
    </actuator>
  </transmission>
  <transmission name="wheel_driving_2_tran">
    <type>transmission_interface/SimpleTransmission</type>
    <joint name="wheel_driving_2">
      <hardwareInterface>hardware_interface/EffortJointInterface</hardwareInterface>
    </joint>
    <actuator name="wheel_driving_2_actr">
      <hardwareInterface>hardware_interface/EffortJointInterface</hardwareInterface>
      <mechanicalReduction>1</mechanicalReduction>
    </actuator>
  </transmission>
  <transmission name="wheel_driving_br_tran">
    <type>transmission_interface/SimpleTransmission</type>
    <joint name="wheel_driving_br">
      <hardwareInterface>hardware_interface/EffortJointInterface</hardwareInterface>
    </joint>
    <actuator name="wheel_driving_br_actr">
      <hardwareInterface>hardware_interface/EffortJointInterface</hardwareInterface>
      <mechanicalReduction>1</mechanicalReduction>
    </actuator>
  </transmission>
  <transmission name="drill_module_tran">
    <type>transmission_interface/SimpleTransmission</type>
    <joint name="drill_module">
      <hardwareInterface>hardware_interface/EffortJointInterface</hardwareInterface>
    </joint>
    <actuator name="drill_module_actr">
      <hardwareInterface>hardware_interface/EffortJointInterface</hardwareInterface>
      <mechanicalReduction>1</mechanicalReduction>
    </actuator>
  </transmission>
  <transmission name="screw_tran">
    <type>transmission_interface/SimpleTransmission</type>
    <joint name="screw">
      <hardwareInterface>hardware_interface/EffortJointInterface</hardwareInterface>
    </joint>
    <actuator name="screw_actr">
      <hardwareInterface>hardware_interface/EffortJointInterface</hardwareInterface>
      <mechanicalReduction>1</mechanicalReduction>
    </actuator>
  </transmission>
  <transmission name="hd_joint_1_tran">
    <type>transmission_interface/SimpleTransmission</type>
    <joint name="hd_joint_1">
      <hardwareInterface>hardware_interface/EffortJointInterface</hardwareInterface>
    </joint>
    <actuator name="hd_joint_1_actr">
      <hardwareInterface>hardware_interface/EffortJointInterface</hardwareInterface>
      <mechanicalReduction>1</mechanicalReduction>
    </actuator>
  </transmission>
  <transmission name="hd_joint_2_tran">
    <type>transmission_interface/SimpleTransmission</type>
    <joint name="hd_joint_2">
      <hardwareInterface>hardware_interface/EffortJointInterface</hardwareInterface>
    </joint>
    <actuator name="hd_joint_2_actr">
      <hardwareInterface>hardware_interface/EffortJointInterface</hardwareInterface>
      <mechanicalReduction>1</mechanicalReduction>
    </actuator>
  </transmission>
  <transmission name="hd_joint_3_tran">
    <type>transmission_interface/SimpleTransmission</type>
    <joint name="hd_joint_3">
      <hardwareInterface>hardware_interface/EffortJointInterface</hardwareInterface>
    </joint>
    <actuator name="hd_joint_3_actr">
      <hardwareInterface>hardware_interface/EffortJointInterface</hardwareInterface>
      <mechanicalReduction>1</mechanicalReduction>
    </actuator>
  </transmission>
  <transmission name="hd_joint_4_tran">
    <type>transmission_interface/SimpleTransmission</type>
    <joint name="hd_joint_4">
      <hardwareInterface>hardware_interface/EffortJointInterface</hardwareInterface>
    </joint>
    <actuator name="hd_joint_4_actr">
      <hardwareInterface>hardware_interface/EffortJointInterface</hardwareInterface>
      <mechanicalReduction>1</mechanicalReduction>
    </actuator>
  </transmission>
  <transmission name="hd_joint_5_tran">
    <type>transmission_interface/SimpleTransmission</type>
    <joint name="hd_joint_5">
      <hardwareInterface>hardware_interface/EffortJointInterface</hardwareInterface>
    </joint>
    <actuator name="hd_joint_5_actr">
      <hardwareInterface>hardware_interface/EffortJointInterface</hardwareInterface>
      <mechanicalReduction>1</mechanicalReduction>
    </actuator>
  </transmission>
  <transmission name="hd_joint_6_tran">
    <type>transmission_interface/SimpleTransmission</type>
    <joint name="hd_joint_6">
      <hardwareInterface>hardware_interface/EffortJointInterface</hardwareInterface>
    </joint>
    <actuator name="hd_joint_6_actr">
      <hardwareInterface>hardware_interface/EffortJointInterface</hardwareInterface>
      <mechanicalReduction>1</mechanicalReduction>
    </actuator>
  </transmission>
  <transmission name="finger_right_tran">
    <type>transmission_interface/SimpleTransmission</type>
    <joint name="finger_right">
      <hardwareInterface>hardware_interface/EffortJointInterface</hardwareInterface>
    </joint>
    <actuator name="finger_right_actr">
      <hardwareInterface>hardware_interface/EffortJointInterface</hardwareInterface>
      <mechanicalReduction>1</mechanicalReduction>
    </actuator>
  </transmission>
  <transmission name="finger_tip_right_tran">
    <type>transmission_interface/SimpleTransmission</type>
    <joint name="finger_tip_right">
      <hardwareInterface>hardware_interface/EffortJointInterface</hardwareInterface>
    </joint>
    <actuator name="finger_tip_right_actr">
      <hardwareInterface>hardware_interface/EffortJointInterface</hardwareInterface>
      <mechanicalReduction>1</mechanicalReduction>
    </actuator>
  </transmission>
  <transmission name="finger_left_tran">
    <type>transmission_interface/SimpleTransmission</type>
    <joint name="finger_left">
      <hardwareInterface>hardware_interface/EffortJointInterface</hardwareInterface>
    </joint>
    <actuator name="finger_left_actr">
      <hardwareInterface>hardware_interface/EffortJointInterface</hardwareInterface>
      <mechanicalReduction>1</mechanicalReduction>
    </actuator>
  </transmission>
  <transmission name="finger_tip_left_tran">
    <type>transmission_interface/SimpleTransmission</type>
    <joint name="finger_tip_left">
      <hardwareInterface>hardware_interface/EffortJointInterface</hardwareInterface>
    </joint>
    <actuator name="finger_tip_left_actr">
      <hardwareInterface>hardware_interface/EffortJointInterface</hardwareInterface>
      <mechanicalReduction>1</mechanicalReduction>
    </actuator>
  </transmission>
  <gazebo>
    <plugin filename="libgazebo_ros_control.so" name="control"/>
  </gazebo>
  <gazebo reference="base_link">
    <material>Gazebo/Silver</material>
    <mu1>0.2</mu1>
    <mu2>0.2</mu2>
    <self_collide>true</self_collide>
    <gravity>true</gravity>
  </gazebo>
  <gazebo reference="1._pivot_steering_v2_1">
    <material>Gazebo/Silver</material>
    <mu1>0.2</mu1>
    <mu2>0.2</mu2>
    <self_collide>true</self_collide>
  </gazebo>
  <gazebo reference="1._pivot_steering_v2_2">
    <material>Gazebo/Silver</material>
    <mu1>0.2</mu1>
    <mu2>0.2</mu2>
    <self_collide>true</self_collide>
  </gazebo>
  <gazebo reference="1._driving_v2_1">
    <material>Gazebo/Silver</material>
    <mu1>0.2</mu1>
    <mu2>0.2</mu2>
    <self_collide>true</self_collide>
  </gazebo>
  <gazebo reference="1._driving_v2_3">
    <material>Gazebo/Silver</material>
    <mu1>0.2</mu1>
    <mu2>0.2</mu2>
    <self_collide>true</self_collide>
  </gazebo>
  <gazebo reference="1._driving_v2_2">
    <material>Gazebo/Silver</material>
    <mu1>0.2</mu1>
    <mu2>0.2</mu2>
    <self_collide>true</self_collide>
  </gazebo>
  <gazebo reference="1._driving_v2_4">
    <material>Gazebo/Silver</material>
    <mu1>0.2</mu1>
    <mu2>0.2</mu2>
    <self_collide>true</self_collide>
  </gazebo>
  <gazebo reference="1._wheel_simplified_v2_1">
    <material>Gazebo/Silver</material>
    <mu1>0.2</mu1>
    <mu2>0.2</mu2>
    <self_collide>true</self_collide>
  </gazebo>
  <gazebo reference="1._wheel_simplified_v2_3">
    <material>Gazebo/Silver</material>
    <mu1>0.2</mu1>
    <mu2>0.2</mu2>
    <self_collide>true</self_collide>
  </gazebo>
  <gazebo reference="1._wheel_simplified_v2_4">
    <material>Gazebo/Silver</material>
    <mu1>0.2</mu1>
    <mu2>0.2</mu2>
    <self_collide>true</self_collide>
  </gazebo>
  <gazebo reference="1._wheel_simplified_v2_2">
    <material>Gazebo/Silver</material>
    <mu1>0.2</mu1>
    <mu2>0.2</mu2>
    <self_collide>true</self_collide>
  </gazebo>
  <gazebo reference="1._element_drill_v3_1">
    <material>Gazebo/Silver</material>
    <mu1>0.2</mu1>
    <mu2>0.2</mu2>
    <self_collide>true</self_collide>
  </gazebo>
  <gazebo reference="1._foret_v2_1">
    <material>Gazebo/Silver</material>
    <mu1>0.2</mu1>
    <mu2>0.2</mu2>
    <self_collide>true</self_collide>
  </gazebo>
  <gazebo reference="1.1_j1j2_v3_1">
    <material>Gazebo/Silver</material>
    <mu1>0.2</mu1>
    <mu2>0.2</mu2>
    <self_collide>true</self_collide>
  </gazebo>
  <gazebo reference="1.1_bras_1_single_c_v2_1">
    <material>Gazebo/Silver</material>
    <mu1>0.2</mu1>
    <mu2>0.2</mu2>
    <self_collide>true</self_collide>
  </gazebo>
  <gazebo reference="1.1_j1j2_v3_3">
    <material>Gazebo/Silver</material>
    <mu1>0.2</mu1>
    <mu2>0.2</mu2>
    <self_collide>true</self_collide>
  </gazebo>
  <gazebo reference="1.1_bras_2_single_c_v2_1">
    <material>Gazebo/Silver</material>
    <mu1>0.2</mu1>
    <mu2>0.2</mu2>
    <self_collide>true</self_collide>
  </gazebo>
  <gazebo reference="1.1_j1j2_v3_2">
    <material>Gazebo/Silver</material>
    <mu1>0.2</mu1>
    <mu2>0.2</mu2>
    <self_collide>true</self_collide>
  </gazebo>
  <gazebo reference="1.1_gripper_single_c_v2_1">
    <material>Gazebo/Silver</material>
    <mu1>0.2</mu1>
    <mu2>0.2</mu2>
    <self_collide>true</self_collide>
  </gazebo>
  <gazebo reference="Arm_A_v6_2">
    <material>Gazebo/Silver</material>
    <mu1>0.2</mu1>
    <mu2>0.2</mu2>
    <self_collide>true</self_collide>
  </gazebo>
  <gazebo reference="Finger_v1_1">
    <material>Gazebo/Silver</material>
    <mu1>0.2</mu1>
    <mu2>0.2</mu2>
    <self_collide>true</self_collide>
  </gazebo>
  <gazebo reference="Arm_A_v6_1">
    <material>Gazebo/Silver</material>
    <mu1>0.2</mu1>
    <mu2>0.2</mu2>
    <self_collide>true</self_collide>
  </gazebo>
  <gazebo reference="Finger_v1_2">
    <material>Gazebo/Silver</material>
    <mu1>0.2</mu1>
    <mu2>0.2</mu2>
    <self_collide>true</self_collide>
  </gazebo>
  <link name="base_link">
    <inertial>
      <origin rpy="0 0 0" xyz="-0.3613340319355315 -0.23528546746907128 0.1983872683584351"/>
      <mass value="48.98789634836586"/>
      <inertia ixx="3.971646" ixy="-0.022504" ixz="0.605064" iyy="5.251389" iyz="0.249432" izz="3.390263"/>
    </inertial>
    <visual>
      <origin rpy="0 0 0" xyz="0 0 0"/>
      <geometry>
        <mesh filename="package://onyx_description_2/meshes/base_link.stl" scale="0.001 0.001 0.001"/>
      </geometry>
      <material name="red"/>
    </visual>
    <collision>
      <origin rpy="0 0 0" xyz="0 0 0"/>
      <geometry>
        <mesh filename="package://onyx_description_2/meshes/base_link.stl" scale="0.001 0.001 0.001"/>
      </geometry>
    </collision>
  </link>
  <link name="1._pivot_steering_v2_1">
    <inertial>
      <origin rpy="0 0 0" xyz="0.0013327059020717402 -0.14344220376800837 0.041707356384150046"/>
      <mass value="9.811514021273375"/>
      <inertia ixx="0.064211" ixy="2.9e-05" ixz="0.044969" iyy="1.826132" iyz="0.001127" izz="1.795757"/>
    </inertial>
    <visual>
      <origin rpy="0 0 0" xyz="0.3 0.448 -0.09"/>
      <geometry>
        <mesh filename="package://onyx_description_2/meshes/1._pivot_steering_v2_1.stl" scale="0.001 0.001 0.001"/>
      </geometry>
      <material name="black"/>
    </visual>
    <collision>
      <origin rpy="0 0 0" xyz="0.3 0.448 -0.09"/>
      <geometry>
        <mesh filename="package://onyx_description_2/meshes/1._pivot_steering_v2_1.stl" scale="0.001 0.001 0.001"/>
      </geometry>
    </collision>
  </link>
  <link name="1._pivot_steering_v2_2">
    <inertial>
      <origin rpy="0 0 0" xyz="0.0023074010701228387 0.14344220376800892 0.04166480027410846"/>
      <mass value="9.811514021273375"/>
      <inertia ixx="0.069555" ixy="-6.9e-05" ixz="0.106054" iyy="1.826132" iyz="-0.001125" izz="1.790413"/>
    </inertial>
    <visual>
      <origin rpy="0 0 0" xyz="0.3 -0.003 -0.091"/>
      <geometry>
        <mesh filename="package://onyx_description_2/meshes/1._pivot_steering_v2_2.stl" scale="0.001 0.001 0.001"/>
      </geometry>
      <material name="black"/>
    </visual>
    <collision>
      <origin rpy="0 0 0" xyz="0.3 -0.003 -0.091"/>
      <geometry>
        <mesh filename="package://onyx_description_2/meshes/1._pivot_steering_v2_2.stl" scale="0.001 0.001 0.001"/>
      </geometry>
    </collision>
  </link>
  <link name="1._driving_v2_1">
    <inertial>
      <origin rpy="0 0 0" xyz="-0.05336323228963802 -0.001790241868722009 -0.2361120772140211"/>
      <mass value="2.150656122682915"/>
      <inertia ixx="0.013956" ixy="-0.0001" ixz="-0.002335" iyy="0.016641" iyz="-6.9e-05" izz="0.003749"/>
    </inertial>
    <visual>
      <origin rpy="0 0 0" xyz="-0.116011 0.591408 -0.062747"/>
      <geometry>
        <mesh filename="package://onyx_description_2/meshes/1._driving_v2_1.stl" scale="0.001 0.001 0.001"/>
      </geometry>
      <material name="silver"/>
    </visual>
    <collision>
      <origin rpy="0 0 0" xyz="-0.116011 0.591408 -0.062747"/>
      <geometry>
        <mesh filename="package://onyx_description_2/meshes/1._driving_v2_1.stl" scale="0.001 0.001 0.001"/>
      </geometry>
    </collision>
  </link>
  <link name="1._driving_v2_3">
    <inertial>
      <origin rpy="0 0 0" xyz="-0.05336302206809551 -0.001790241868722231 -0.23611208152895444"/>
      <mass value="2.150656122682915"/>
      <inertia ixx="0.013956" ixy="-0.0001" ixz="-0.002335" iyy="0.016641" iyz="-6.9e-05" izz="0.003749"/>
    </inertial>
    <visual>
      <origin rpy="0 0 0" xyz="0.716864 0.591408 -0.084264"/>
      <geometry>
        <mesh filename="package://onyx_description_2/meshes/1._driving_v2_3.stl" scale="0.001 0.001 0.001"/>
      </geometry>
      <material name="silver"/>
    </visual>
    <collision>
      <origin rpy="0 0 0" xyz="0.716864 0.591408 -0.084264"/>
      <geometry>
        <mesh filename="package://onyx_description_2/meshes/1._driving_v2_3.stl" scale="0.001 0.001 0.001"/>
      </geometry>
    </collision>
  </link>
  <link name="1._driving_v2_2">
    <inertial>
      <origin rpy="0 0 0" xyz="-0.06173523819166351 -0.0017906129843300866 -0.23406282227931108"/>
      <mass value="2.150656122682915"/>
      <inertia ixx="0.013777" ixy="-0.000102" ixz="-0.002692" iyy="0.016641" iyz="-6.5e-05" izz="0.003928"/>
    </inertial>
    <visual>
      <origin rpy="0 0 0" xyz="-0.114777 -0.146408 -0.048954"/>
      <geometry>
        <mesh filename="package://onyx_description_2/meshes/1._driving_v2_2.stl" scale="0.001 0.001 0.001"/>
      </geometry>
      <material name="silver"/>
    </visual>
    <collision>
      <origin rpy="0 0 0" xyz="-0.114777 -0.146408 -0.048954"/>
      <geometry>
        <mesh filename="package://onyx_description_2/meshes/1._driving_v2_2.stl" scale="0.001 0.001 0.001"/>
      </geometry>
    </collision>
  </link>
  <link name="1._driving_v2_4">
    <inertial>
      <origin rpy="0 0 0" xyz="-0.061736017683869604 -0.0017906129843306695 -0.234062118380695"/>
      <mass value="2.150656122682915"/>
      <inertia ixx="0.013777" ixy="-0.000102" ixz="-0.002692" iyy="0.016641" iyz="-6.5e-05" izz="0.003928"/>
    </inertial>
    <visual>
      <origin rpy="0 0 0" xyz="0.716803 -0.146408 -0.100108"/>
      <geometry>
        <mesh filename="package://onyx_description_2/meshes/1._driving_v2_4.stl" scale="0.001 0.001 0.001"/>
      </geometry>
      <material name="silver"/>
    </visual>
    <collision>
      <origin rpy="0 0 0" xyz="0.716803 -0.146408 -0.100108"/>
      <geometry>
        <mesh filename="package://onyx_description_2/meshes/1._driving_v2_4.stl" scale="0.001 0.001 0.001"/>
      </geometry>
    </collision>
  </link>
  <link name="1._wheel_simplified_v2_1">
    <inertial>
      <origin rpy="0 0 0" xyz="-0.039472055537907336 -0.0013188678711943402 0.0024275550921873112"/>
      <mass value="23.722548877018745"/>
      <inertia ixx="0.348962" ixy="0.004735" ixz="-0.008717" iyy="0.207419" iyz="-0.000291" izz="0.207797"/>
    </inertial>
    <visual>
      <origin rpy="0 0 0" xyz="-0.139795 -0.147791 0.219889"/>
      <geometry>
        <mesh filename="package://onyx_description_2/meshes/1._wheel_simplified_v2_1.stl" scale="0.001 0.001 0.001"/>
      </geometry>
      <material name="white"/>
    </visual>
    <collision>
      <origin rpy="0 0 0" xyz="-0.139795 -0.147791 0.219889"/>
      <geometry>
        <mesh filename="package://onyx_description_2/meshes/1._wheel_simplified_v2_1.stl" scale="0.001 0.001 0.001"/>
      </geometry>
    </collision>
  </link>
  <link name="1._wheel_simplified_v2_3">
    <inertial>
      <origin rpy="0 0 0" xyz="-0.03947183503011442 -0.0013188678711952284 0.0024282589908035113"/>
      <mass value="23.722548877018745"/>
      <inertia ixx="0.348962" ixy="0.004735" ixz="-0.008717" iyy="0.207419" iyz="-0.000291" izz="0.207797"/>
    </inertial>
    <visual>
      <origin rpy="0 0 0" xyz="0.691786 -0.147791 0.168735"/>
      <geometry>
        <mesh filename="package://onyx_description_2/meshes/1._wheel_simplified_v2_3.stl" scale="0.001 0.001 0.001"/>
      </geometry>
      <material name="white"/>
    </visual>
    <collision>
      <origin rpy="0 0 0" xyz="0.691786 -0.147791 0.168735"/>
      <geometry>
        <mesh filename="package://onyx_description_2/meshes/1._wheel_simplified_v2_3.stl" scale="0.001 0.001 0.001"/>
      </geometry>
    </collision>
  </link>
  <link name="1._wheel_simplified_v2_4">
    <inertial>
      <origin rpy="0 0 0" xyz="-0.03953322987191166 -0.0013184967555868177 0.0010210764613669265"/>
      <mass value="23.722548877018745"/>
      <inertia ixx="0.349404" ixy="0.004742" ixz="-0.003672" iyy="0.207419" iyz="-0.000122" izz="0.207356"/>
    </inertial>
    <visual>
      <origin rpy="0 0 0" xyz="-0.150584 0.590025 0.205035"/>
      <geometry>
        <mesh filename="package://onyx_description_2/meshes/1._wheel_simplified_v2_4.stl" scale="0.001 0.001 0.001"/>
      </geometry>
      <material name="white"/>
    </visual>
    <collision>
      <origin rpy="0 0 0" xyz="-0.150584 0.590025 0.205035"/>
      <geometry>
        <mesh filename="package://onyx_description_2/meshes/1._wheel_simplified_v2_4.stl" scale="0.001 0.001 0.001"/>
      </geometry>
    </collision>
  </link>
  <link name="1._wheel_simplified_v2_2">
    <inertial>
      <origin rpy="0 0 0" xyz="-0.03953301965036915 -0.0013184967555871507 0.0010210721464317118"/>
      <mass value="23.722548877018745"/>
      <inertia ixx="0.349404" ixy="0.004742" ixz="-0.003672" iyy="0.207419" iyz="-0.000122" izz="0.207356"/>
    </inertial>
    <visual>
      <origin rpy="0 0 0" xyz="0.682291 0.590025 0.183518"/>
      <geometry>
        <mesh filename="package://onyx_description_2/meshes/1._wheel_simplified_v2_2.stl" scale="0.001 0.001 0.001"/>
      </geometry>
      <material name="white"/>
    </visual>
    <collision>
      <origin rpy="0 0 0" xyz="0.682291 0.590025 0.183518"/>
      <geometry>
        <mesh filename="package://onyx_description_2/meshes/1._wheel_simplified_v2_2.stl" scale="0.001 0.001 0.001"/>
      </geometry>
    </collision>
  </link>
  <link name="1._element_drill_v3_1">
    <inertial>
      <origin rpy="0 0 0" xyz="-0.0513141706983431 0.08221396100891368 -0.13869483209325395"/>
      <mass value="7.507949209271667"/>
      <inertia ixx="0.275242" ixy="0.001311" ixz="-0.019318" iyy="0.26604" iyz="0.013401" izz="0.03028"/>
    </inertial>
    <visual>
      <origin rpy="0 0 0" xyz="0.643 0.2975 -0.779165"/>
      <geometry>
        <mesh filename="package://onyx_description_2/meshes/1._element_drill_v3_1.stl" scale="0.001 0.001 0.001"/>
      </geometry>
      <material name="grey_transparent"/>
    </visual>
    <collision>
      <origin rpy="0 0 0" xyz="0.643 0.2975 -0.779165"/>
      <geometry>
        <mesh filename="package://onyx_description_2/meshes/1._element_drill_v3_1.stl" scale="0.001 0.001 0.001"/>
      </geometry>
    </collision>
  </link>
  <link name="1._foret_v2_1">
    <inertial>
      <origin rpy="0 0 0" xyz="-9.824394509250212e-06 2.6079352202057482e-05 -0.3388184333033617"/>
      <mass value="1.9633991132983974"/>
      <inertia ixx="0.069287" ixy="0.0" ixz="-5e-06" iyy="0.069287" iyz="-2e-06" izz="0.000163"/>
    </inertial>
    <visual>
      <origin rpy="0 0 0" xyz="0.7185 0.19625 -0.686365"/>
      <geometry>
        <mesh filename="package://onyx_description_2/meshes/1._foret_v2_1.stl" scale="0.001 0.001 0.001"/>
      </geometry>
      <material name="red"/>
    </visual>
    <collision>
      <origin rpy="0 0 0" xyz="0.7185 0.19625 -0.686365"/>
      <geometry>
        <mesh filename="package://onyx_description_2/meshes/1._foret_v2_1.stl" scale="0.001 0.001 0.001"/>
      </geometry>
    </collision>
  </link>
  <link name="1.1_j1j2_v3_1">
    <inertial>
      <origin rpy="0 0 0" xyz="-0.00027217681434484053 -0.01874965815887239 0.10480043065496542"/>
      <mass value="4.344736178343352"/>
      <inertia ixx="0.027954" ixy="0.000104" ixz="8e-06" iyy="0.020469" iyz="0.001795" izz="0.018137"/>
    </inertial>
    <visual>
      <origin rpy="0 0 0" xyz="0.07 0.2225 -0.195"/>
      <geometry>
        <mesh filename="package://onyx_description_2/meshes/1.1_j1j2_v3_1.stl" scale="0.001 0.001 0.001"/>
      </geometry>
      <material name="grey"/>
    </visual>
    <collision>
      <origin rpy="0 0 0" xyz="0.07 0.2225 -0.195"/>
      <geometry>
        <mesh filename="package://onyx_description_2/meshes/1.1_j1j2_v3_1.stl" scale="0.001 0.001 0.001"/>
      </geometry>
    </collision>
  </link>
  <link name="1.1_bras_1_single_c_v2_1">
    <inertial>
      <origin rpy="0 0 0" xyz="0.18599999999999656 0.011067557585022869 -1.27675647831893e-15"/>
      <mass value="3.1139206406559206"/>
      <inertia ixx="0.005977" ixy="0.0" ixz="0.0" iyy="0.069339" iyz="0.0" izz="0.067529"/>
    </inertial>
    <visual>
      <origin rpy="0 0 0" xyz="0.07 0.341 -0.3135"/>
      <geometry>
        <mesh filename="package://onyx_description_2/meshes/1.1_bras_1_single_c_v2_1.stl" scale="0.001 0.001 0.001"/>
      </geometry>
      <material name="grey"/>
    </visual>
    <collision>
      <origin rpy="0 0 0" xyz="0.07 0.341 -0.3135"/>
      <geometry>
        <mesh filename="package://onyx_description_2/meshes/1.1_bras_1_single_c_v2_1.stl" scale="0.001 0.001 0.001"/>
      </geometry>
    </collision>
  </link>
  <link name="1.1_j1j2_v3_3">
    <inertial>
      <origin rpy="0 0 0" xyz="-0.0002721768143455483 0.10480043065495545 0.018749658158870752"/>
      <mass value="4.344736178343352"/>
      <inertia ixx="0.027954" ixy="8e-06" ixz="-0.000104" iyy="0.018137" iyz="-0.001795" izz="0.020469"/>
    </inertial>
    <visual>
      <origin rpy="0 0 0" xyz="-0.302 0.341 -0.3135"/>
      <geometry>
        <mesh filename="package://onyx_description_2/meshes/1.1_j1j2_v3_3.stl" scale="0.001 0.001 0.001"/>
      </geometry>
      <material name="grey"/>
    </visual>
    <collision>
      <origin rpy="0 0 0" xyz="-0.302 0.341 -0.3135"/>
      <geometry>
        <mesh filename="package://onyx_description_2/meshes/1.1_j1j2_v3_3.stl" scale="0.001 0.001 0.001"/>
      </geometry>
    </collision>
  </link>
  <link name="1.1_bras_2_single_c_v2_1">
    <inertial>
      <origin rpy="0 0 0" xyz="-5.090372567906343e-14 0.0033315049373294214 0.15487679697152218"/>
      <mass value="2.3051495546208427"/>
      <inertia ixx="0.026991" ixy="0.0" ixz="0.0" iyy="0.027883" iyz="-0.00098" izz="0.004302"/>
    </inertial>
    <visual>
      <origin rpy="0 0 0" xyz="-0.302 0.2225 -0.432"/>
      <geometry>
        <mesh filename="package://onyx_description_2/meshes/1.1_bras_2_single_c_v2_1.stl" scale="0.001 0.001 0.001"/>
      </geometry>
      <material name="grey"/>
    </visual>
    <collision>
      <origin rpy="0 0 0" xyz="-0.302 0.2225 -0.432"/>
      <geometry>
        <mesh filename="package://onyx_description_2/meshes/1.1_bras_2_single_c_v2_1.stl" scale="0.001 0.001 0.001"/>
      </geometry>
    </collision>
  </link>
  <link name="1.1_j1j2_v3_2">
    <inertial>
      <origin rpy="0 0 0" xyz="0.00027217681433833185 -0.10480043065497505 0.018749658158869087"/>
      <mass value="4.344736178343352"/>
      <inertia ixx="0.027954" ixy="8e-06" ixz="0.000104" iyy="0.018137" iyz="0.001795" izz="0.020469"/>
    </inertial>
    <visual>
      <origin rpy="0 0 0" xyz="-0.302 0.2065 -0.704"/>
      <geometry>
        <mesh filename="package://onyx_description_2/meshes/1.1_j1j2_v3_2.stl" scale="0.001 0.001 0.001"/>
      </geometry>
      <material name="grey"/>
    </visual>
    <collision>
      <origin rpy="0 0 0" xyz="-0.302 0.2065 -0.704"/>
      <geometry>
        <mesh filename="package://onyx_description_2/meshes/1.1_j1j2_v3_2.stl" scale="0.001 0.001 0.001"/>
      </geometry>
    </collision>
  </link>
  <link name="1.1_gripper_single_c_v2_1">
    <inertial>
      <origin rpy="0 0 0" xyz="-0.00012272189334172623 -0.00013910374700421002 0.049867298136252125"/>
      <mass value="0.4705692004888986"/>
      <inertia ixx="0.001186" ixy="0.0" ixz="0.0" iyy="0.001335" iyz="4e-06" izz="0.000306"/>
    </inertial>
    <visual>
      <origin rpy="0 0 0" xyz="-0.302 0.325 -0.8225"/>
      <geometry>
        <mesh filename="package://onyx_description_2/meshes/1.1_gripper_single_c_v2_1.stl" scale="0.001 0.001 0.001"/>
      </geometry>
      <material name="grey"/>
    </visual>
    <collision>
      <origin rpy="0 0 0" xyz="-0.302 0.325 -0.8225"/>
      <geometry>
        <mesh filename="package://onyx_description_2/meshes/1.1_gripper_single_c_v2_1.stl" scale="0.001 0.001 0.001"/>
      </geometry>
    </collision>
  </link>
  <link name="Arm_A_v6_2">
    <inertial>
      <origin rpy="0 0 0" xyz="0.018951414122021337 -0.003749922369615577 0.03443129704231307"/>
      <mass value="0.11091056155247334"/>
      <inertia ixx="0.000106" ixy="-0.0" ixz="1.1e-05" iyy="0.000118" iyz="-0.0" izz="1.4e-05"/>
    </inertial>
    <visual>
      <origin rpy="0 0 0" xyz="-0.31698 0.34752 -0.9272"/>
      <geometry>
        <mesh filename="package://onyx_description_2/meshes/Arm_A_v6_2.stl" scale="0.001 0.001 0.001"/>
      </geometry>
      <material name="black"/>
    </visual>
    <collision>
      <origin rpy="0 0 0" xyz="-0.31698 0.34752 -0.9272"/>
      <geometry>
        <mesh filename="package://onyx_description_2/meshes/Arm_A_v6_2.stl" scale="0.001 0.001 0.001"/>
      </geometry>
    </collision>
  </link>
  <link name="Finger_v1_1">
    <inertial>
      <origin rpy="0 0 0" xyz="0.009336809759994846 0.022500081170689412 8.540730690231868e-06"/>
      <mass value="0.21086382762249625"/>
      <inertia ixx="3.4e-05" ixy="0.0" ixz="0.0" iyy="3.6e-05" iyz="0.0" izz="5.6e-05"/>
    </inertial>
    <visual>
      <origin rpy="0 0 0" xyz="-0.319898 0.34752 -1.01378"/>
      <geometry>
        <mesh filename="package://onyx_description_2/meshes/Finger_v1_1.stl" scale="0.001 0.001 0.001"/>
      </geometry>
      <material name="black"/>
    </visual>
    <collision>
      <origin rpy="0 0 0" xyz="-0.319898 0.34752 -1.01378"/>
      <geometry>
        <mesh filename="package://onyx_description_2/meshes/Finger_v1_1.stl" scale="0.001 0.001 0.001"/>
      </geometry>
    </collision>
  </link>
  <link name="Arm_A_v6_1">
    <inertial>
      <origin rpy="0 0 0" xyz="-0.018951259013647637 -0.0037499225220117838 0.034431297042313624"/>
      <mass value="0.11091056155247334"/>
      <inertia ixx="0.000106" ixy="-0.0" ixz="-1.1e-05" iyy="0.000118" iyz="0.0" izz="1.4e-05"/>
    </inertial>
    <visual>
      <origin rpy="0 0 0" xyz="-0.28698 0.34752 -0.9272"/>
      <geometry>
        <mesh filename="package://onyx_description_2/meshes/Arm_A_v6_1.stl" scale="0.001 0.001 0.001"/>
      </geometry>
      <material name="black"/>
    </visual>
    <collision>
      <origin rpy="0 0 0" xyz="-0.28698 0.34752 -0.9272"/>
      <geometry>
        <mesh filename="package://onyx_description_2/meshes/Arm_A_v6_1.stl" scale="0.001 0.001 0.001"/>
      </geometry>
    </collision>
  </link>
  <link name="Finger_v1_2">
    <inertial>
      <origin rpy="0 0 0" xyz="-0.00933665465162059 0.022500073937683163 8.540730690898002e-06"/>
      <mass value="0.21086382762249625"/>
      <inertia ixx="3.4e-05" ixy="0.0" ixz="-0.0" iyy="3.6e-05" iyz="-0.0" izz="5.6e-05"/>
    </inertial>
    <visual>
      <origin rpy="0 0 0" xyz="-0.284062 0.34752 -1.01378"/>
      <geometry>
        <mesh filename="package://onyx_description_2/meshes/Finger_v1_2.stl" scale="0.001 0.001 0.001"/>
      </geometry>
      <material name="black"/>
    </visual>
    <collision>
      <origin rpy="0 0 0" xyz="-0.284062 0.34752 -1.01378"/>
      <geometry>
        <mesh filename="package://onyx_description_2/meshes/Finger_v1_2.stl" scale="0.001 0.001 0.001"/>
      </geometry>
    </collision>
  </link>
  <joint name="pivot_right" type="continuous">
    <origin rpy="0 0 0" xyz="-0.3 -0.448 0.09"/>
    <parent link="base_link"/>
    <child link="1._pivot_steering_v2_1"/>
    <axis xyz="0.0 1.0 -0.0"/>
  </joint>
  <joint name="pivot_left" type="continuous">
    <origin rpy="0 0 0" xyz="-0.3 0.003 0.091"/>
    <parent link="base_link"/>
    <child link="1._pivot_steering_v2_2"/>
    <axis xyz="0.0 -1.0 0.0"/>
  </joint>
  <joint name="wheel_steering_2" type="continuous">
    <origin rpy="0 0 0" xyz="0.416011 -0.143408 -0.027253"/>
    <parent link="1._pivot_steering_v2_1"/>
    <child link="1._driving_v2_1"/>
    <axis xyz="0.025826 0.0 0.999666"/>
  </joint>
  <joint name="wheel_steering_4" type="continuous">
    <origin rpy="0 0 0" xyz="-0.416864 -0.143408 -0.005736"/>
    <parent link="1._pivot_steering_v2_1"/>
    <child link="1._driving_v2_3"/>
    <axis xyz="-0.025826 -0.0 -0.999666"/>
  </joint>
  <joint name="wheel_steering_1" type="continuous">
    <origin rpy="0 0 0" xyz="0.414777 0.143408 -0.042046"/>
    <parent link="1._pivot_steering_v2_2"/>
    <child link="1._driving_v2_2"/>
    <axis xyz="-0.061399 0.0 -0.998113"/>
  </joint>
  <joint name="wheel_steering_3" type="continuous">
    <origin rpy="0 0 0" xyz="-0.416803 0.143408 0.009108"/>
    <parent link="1._pivot_steering_v2_2"/>
    <child link="1._driving_v2_4"/>
    <axis xyz="0.061399 -0.0 0.998113"/>
  </joint>
  <joint name="wheel_driving_1" type="continuous">
    <origin rpy="0 0 0" xyz="0.025018 0.001383 -0.268843"/>
    <parent link="1._driving_v2_2"/>
    <child link="1._wheel_simplified_v2_1"/>
    <axis xyz="0.997559 0.03333 -0.061365"/>
  </joint>
  <joint name="wheel_driving_3" type="continuous">
    <origin rpy="0 0 0" xyz="0.025017 0.001383 -0.268843"/>
    <parent link="1._driving_v2_4"/>
    <child link="1._wheel_simplified_v2_3"/>
    <axis xyz="0.997559 0.03333 -0.061365"/>
  </joint>
  <joint name="wheel_driving_2" type="continuous">
    <origin rpy="0 0 0" xyz="0.034573 0.001383 -0.267782"/>
    <parent link="1._driving_v2_1"/>
    <child link="1._wheel_simplified_v2_4"/>
    <axis xyz="0.999111 0.03333 -0.025812"/>
  </joint>
  <joint name="wheel_driving_4" type="continuous">
    <origin rpy="0 0 0" xyz="0.034573 0.001383 -0.267782"/>
    <parent link="1._driving_v2_3"/>
    <child link="1._wheel_simplified_v2_2"/>
    <axis xyz="0.999111 0.03333 -0.025812"/>
  </joint>
  <joint name="drill_module" type="prismatic">
    <origin rpy="0 0 0" xyz="-0.643 -0.2975 0.779165"/>
    <parent link="base_link"/>
    <child link="1._element_drill_v3_1"/>
    <axis xyz="0.0 0.0 1.0"/>
    <limit effort="100" lower="-0.64" upper="0.0" velocity="100"/>
  </joint>
  <joint name="screw" type="continuous">
    <origin rpy="0 0 0" xyz="-0.0755 0.10125 -0.0928"/>
    <parent link="1._element_drill_v3_1"/>
    <child link="1._foret_v2_1"/>
    <axis xyz="0.0 -0.0 -1.0"/>
  </joint>
  <joint name="hd_joint_1" type="continuous">
    <origin rpy="0 0 0" xyz="-0.07 -0.2225 0.195"/>
    <parent link="base_link"/>
    <child link="1.1_j1j2_v3_1"/>
    <axis xyz="0.0 0.0 -1.0"/>
  </joint>
  <joint name="hd_joint_2" type="continuous">
    <origin rpy="0 0 0" xyz="0.0 -0.1185 0.1185"/>
    <parent link="1.1_j1j2_v3_1"/>
    <child link="1.1_bras_1_single_c_v2_1"/>
    <axis xyz="0.0 1.0 0.0"/>
  </joint>
  <joint name="hd_joint_3" type="continuous">
    <origin rpy="0 0 0" xyz="0.372 0.0 0.0"/>
    <parent link="1.1_bras_1_single_c_v2_1"/>
    <child link="1.1_j1j2_v3_3"/>
    <axis xyz="-0.0 -1.0 0.0"/>
  </joint>
  <joint name="hd_joint_4" type="continuous">
    <origin rpy="0 0 0" xyz="0.0 0.1185 0.1185"/>
    <parent link="1.1_j1j2_v3_3"/>
    <child link="1.1_bras_2_single_c_v2_1"/>
    <axis xyz="0.0 -0.0 -1.0"/>
  </joint>
  <joint name="hd_joint_5" type="continuous">
    <origin rpy="0 0 0" xyz="0.0 0.016 0.272"/>
    <parent link="1.1_bras_2_single_c_v2_1"/>
    <child link="1.1_j1j2_v3_2"/>
    <axis xyz="0.0 1.0 -0.0"/>
  </joint>
  <joint name="hd_joint_6" type="continuous">
    <origin rpy="0 0 0" xyz="0.0 -0.1185 0.1185"/>
    <parent link="1.1_j1j2_v3_2"/>
    <child link="1.1_gripper_single_c_v2_1"/>
    <axis xyz="0.0 -0.0 -1.0"/>
  </joint>
  <joint name="finger_right" type="continuous">
    <origin rpy="0 0 0" xyz="0.01498 -0.02252 0.1047"/>
    <parent link="1.1_gripper_single_c_v2_1"/>
    <child link="Arm_A_v6_2"/>
    <axis xyz="0.0 1.0 -0.0"/>
  </joint>
  <joint name="finger_tip_right" type="continuous">
    <origin rpy="0 0 0" xyz="0.002918 0.0 0.08658"/>
    <parent link="Arm_A_v6_2"/>
    <child link="Finger_v1_1"/>
    <axis xyz="-0.0 -1.0 0.0"/>
  </joint>
  <joint name="finger_left" type="continuous">
    <origin rpy="0 0 0" xyz="-0.01502 -0.02252 0.1047"/>
    <parent link="1.1_gripper_single_c_v2_1"/>
    <child link="Arm_A_v6_1"/>
    <axis xyz="0.0 1.0 -0.0"/>
  </joint>
  <joint name="finger_tip_left" type="continuous">
    <origin rpy="0 0 0" xyz="-0.002918 0.0 0.08658"/>
    <parent link="Arm_A_v6_1"/>
    <child link="Finger_v1_2"/>
    <axis xyz="-0.0 -1.0 0.0"/>
  </joint>
</robot>
